Workbook

Sheet 框架对标原文底稿
A1: 一级指标 | B1: 二级指标 | C1: 三级指标 | D1: 关键字说明 | E1: 人民银行转型金融要求 | F1: 人民银行钢铁行业转型金融标准 | G1: 企业可持续披露准则第1号——气候（试行） | H1: 《河北省钢铁行业转型金融工作指引（2025年版）》 | I1: 沪深北上市公司可持续披露指引 | J1: 工业和信息化部《钢铁行业规范条件（2025年版）》 | K1: 其他国内政策 | L1: IIGCC《净零投资框架1.0》 | M1: ICMA气候转型债券指引（CTB）和气候转型融资手册（CTF） | N1: 《TPI方法论报告：管理质量和碳绩效》第五版 | O1: 惠誉常青《转型评估方法：石油和天然气部门》 | P1: 《TCFD 指标、目标和转型计划指南》 | Q1: TPT《英国转型计划工作组的转型计划披露框架》 | R1: SASB——《对可持续核算准则理事会（SASB）标准的修订（征求意见稿）》 | S1: GFANZ《金融机构净零转型计划框架》 | T1: 企业信息披露情况（宝山钢铁） | U1: 企业信息披露情况（中信特钢） | V1: 分析
A2: 目标与战略 | B2: 目标和承诺 | C2: 碳中和目标 | D2: 企业承诺转型目标与国家碳达峰碳中和目标一致，服务于国家碳达峰碳中和目标；制定减排目标是指企业制定短期（如2024—2025年）、中期（2026—2030年）和长期（至2060年）的目标，且目标符合所在行业的先进性水平 | E2: 转型主体应当对照国家碳达峰碳中和目标，制定并披露科学合理的碳减排目标，主要内容和要求包括：（1）转型主体层面的碳达峰碳中和目标不得落后于国家碳达峰碳中和目标要求；（2）包括短期、中期和长期目标，以定量的碳排放总量或者单位产品碳排放强度表示。 | G2: 第四十一条 企业应当披露其为监控实现战略目标的进展而设定的定量和定性气候目标，以及国家法律法规、战略规划要求其实现的气候目标，包括温室气体排放目标 | H2: 一（一）2.有整体转型方案。方案应遵循以下原则：一是有科学合理的碳减排目标。目标要坚持显著贡献原则和一致性原则”，应将商业可持续与双碳目标有机结合，不得落后于国家碳达峰碳中和目标要求。短期目标要以定量的碳排放强度表示，中、长期目标要兼顾碳排放总量。 | L2: 1. 根据法律义务、信托义务和行业最佳实践（如TCFD和ISSB）； 2.承诺到2050年或更早实现投资组合净零排放，并获得董事会的明确认可； | M2: CTF：要素1.发行人的气候转型战略和治理：推荐信息和指标： • 长期、以科学为基础的目标，以符合《巴黎协定》的目标； CTB：高排放SLBs发行人应根据具体行业和本地情况选择KPI，并设定具有雄心的SPT，基于多种基准方法的结合，例如历史和经外部验证的数据、同行选择的数据以及行业或部门标准，融入公认的“最佳可用技术”（BAT）或其他行业/部门的替代指标。目标至少应与官方国家/地区/国际目标保持一致，并在可能的情况下，力求超越这些水平。 | N2: 企业设定了温室气体减排目标，目标可能是以定量或非定量形式，可能覆盖范围1和范围2和/或范围3温室气体排放。 企业以相对或绝对方式设定了温室气体减排的定量目标（范围1和范围2和/或范围3）。 | O2: （钢铁）对于2050目标从排放量、排放强度进行了等级划分： （1）有针对性地减少范围1和范围2的绝对排放量：按照企业是否有目标与数据及其详细程度（有无、详细程度），分6个评分阈值（0-5）进行评价； （2）有目标地减少范围3的绝对排放量:按照企业是否有目标与数据及其详细程度（有无、详细程度），分6个评分阈值（0-5）进行评价； （3）有针对性地减少范围1和范围2排放强度:按照企业是否有目标与数据及其详细程度（有无、详细程度），分6个评分阈值（0-5）进行评价； | P2: （1）与战略保持一致：组织的转型计划与其整体战略保持一致，并且描述了下列内容：  举措——组织将如何在规定的时间范围内实现目标。  温控目标——与全球升温目标、相关监管要求和/或部门脱碳战略保持一致。 | Q2: 1.1 战略愿景 主体应当披露其转型计划中的战略愿景。这包括主体在向低温室气体排放、气候韧性经济转型过程中，为响应并推动转型而设定的目标与优先事项，同时说明主体将如何以把握机遇、避免对利益相关方和社会造成不利影响、保护自然环境的方式来追求这些目标和优先事项。 披露建议 作为此部分的内容，主体应当披露： a. 其目标与优先事项： i. 旨在减少其运营或价值链中范围 1、范围 2 和范围 3 温室气体排放的目标与优先事项 ii. 旨在增强其对气候变化的适应能力，并应对向低温室气体排放、气候韧性经济转型所带来的风险与机遇的目标与优先事项 iii. 旨在利用其可用的杠杆与能力，嵌入并加速向低温室气体排放、气候韧性经济转型的目标与优先事项 b. 其是否以及如何识别、评估并考量转型计划对利益相关方（如员工、价值链合作伙伴、客户、社会（如当地社区）、经济和自然环境）的影响与依赖关系，以及这些影响与依赖关系在整个价值链中可能引发的可持续性相关风险与机遇 c. 其在多大程度上考量并遵循了外部要求、承诺、基于科学的目标、转型路径、路线图或情景，其中可能包括： i. 政府做出的国家或国际承诺 ii. 法律或法规要求其达成的任何目标 iii. 行业路径、路线图或其他气候情景 iv. 自愿性承诺（例如，现有的公开承诺、组织和行业标准、合同关系、行为准则等） d. 在 1.1a 的目标与优先事项之间识别出的任何潜在权衡、协同效应或共同效益 e. 其为衡量进展而设定的任何短期、中期和长期目标及里程碑，包括在转型规划背景下如何定义短期、中期和长期 | R2: 主体应当披露其管理范围 1 温室气体（GHG）排放的长期与短期战略或计划，包括减排目标，以及针对这些目标的绩效分析。 1.1 目标披露 1.2 目标设定与监控 1.3 绩效分析 | S2: 目标与优先事项 目标，即在 2050 年或更早实现净零排放，该目标需符合基于科学的路径，以将升温限制在 1.5℃以内。明确界定可衡量的中期和长期目标与战略时间线，为推动实体经济减排而需采取的净零转型融资优先战略。 ・为 2050 年净零目标制定的短期、中期和长期战略愿景、承诺及实现路径 | T2: 来源：24年可持续发展报告 制定了中长期减碳目标，以2020年为基准年，2025年减碳8%，2035年力争减碳30%，2050年力争实现碳中和。 2035年力争减碳30%脚注：以公司运营范围为边界，包括范围一和范围二 | U2: 来源：24年可持续发展报告 2060 年前实现“碳中和”的目标 | V2: 碳达峰、碳中和目标属于企业转型战略层面的核心承诺指标，能够直接反映企业对国家“双碳”政策目标的响应程度及其长期转型方向。相关目标在政策框架中具有明确定位，且上市钢铁企业普遍存在定性或定量披露，具备较好的可比性与可得性，建议作为目标与战略维度的基础性指标予以保留。
C3: 碳达峰目标 | D3: 企业承诺转型目标与国家碳达峰碳中和目标一致，服务于国家碳达峰碳中和目标；制定减排目标是指企业制定短期（如2024—2025年）、中期（2026—2030年）和长期（至2060年）的目标，且目标符合所在行业的先进性水平 | E3: 转型主体应当对照国家碳达峰碳中和目标，制定并披露科学合理的碳减排目标，主要内容和要求包括：（1）转型主体层面的碳达峰碳中和目标不得落后于国家碳达峰碳中和目标要求；（2）包括短期、中期和长期目标，以定量的碳排放总量或者单位产品碳排放强度表示。 | G3: 第四十一条 企业应当披露其为监控实现战略目标的进展而设定的定量和定性气候目标，以及国家法律法规、战略规划要求其实现的气候目标，包括温室气体排放目标 | H3: 一（一）2.有整体转型方案。方案应遵循以下原则：一是有科学合理的碳减排目标。目标要坚持显著贡献原则和一致性原则”，应将商业可持续与双碳目标有机结合，不得落后于国家碳达峰碳中和目标要求。短期目标要以定量的碳排放强度表示，中、长期目标要兼顾碳排放总量。 | L3: 4. 脱碳计划：一套量化的措施，通过减少温室气体和增加相关的绿色收入来实现中短期科学目标； 6. 目标：减少温室气体排放的短期和中期科学目标； 7. 雄心：2050年的长期目标与实现全球净零排放相一致。 6. 雄心：2050年的长期目标与实现全球净零排放目标一致，以及与之一致的中期目标（国家自主贡献绝对排放目标）。 | M3: CTF：要素1.发行人的气候转型战略和治理：推荐信息和指标： • 与长期目标发展轨迹相关的短期和中期科学基础的中间目标，符合相关区域、行业或国际气候变化情景。 CTB：高排放SLBs发行人应根据具体行业和本地情况选择KPI，并设定具有雄心的SPT，基于多种基准方法的结合，例如历史和经外部验证的数据、同行选择的数据以及行业或部门标准，融入公认的“最佳可用技术”（BAT）或其他行业/部门的替代指标。目标至少应与官方国家/地区/国际目标保持一致，并在可能的情况下，力求超越这些水平。 | N3: 企业以相对或绝对的形式设定了定量且长期（超过5年）的减排目标（范围1和范围2和/或范围3）。 | O3: （钢铁）对于2030目标从排放量、排放强度进行了等级划分： （1）有针对性地减少范围1和范围2的绝对排放量：按照企业是否有目标与数据及其详细程度（有无、详细程度），分6个评分阈值（0-5）进行评价； （2）有目标地减少范围3的绝对排放量:按照企业是否有目标与数据及其详细程度（有无、详细程度），分6个评分阈值（0-5）进行评价； （3）有针对性地减少范围1和范围2排放强度:按照企业是否有目标与数据及其详细程度（有无、详细程度），分6个评分阈值（0-5）进行评价； | P3: （2）目标：制定基于科学的定量和定性目标。对于温室气体排放目标而言，明确温室气体排放类型和范围，以及跨地区、时间范围或活动的温室气体排放程度。 | Q3: 4. 指标与目标 4.3 温室气体指标与目标 主体应当披露其为推动和监控转型计划战略愿景进展所使用的温室气体排放与清除指标及目标，并至少每年针对这些指标和目标进行一次报告。 披露建议…… | R3: 绩效分析的详细要求 主体应当讨论其减排目标，并分析针对这些目标的绩效表现，包括（如适用）： 2.1 减排目标的范围（例如，目标所覆盖的总排放量占比） 2.2 目标类型：说明目标是绝对目标还是强度目标；若为强度目标，需披露指标分母 2.3 基准年减排比例：说明相对于基准年的减排百分比，基准年是评估目标达成情况的起始年份 2.4 减排时间线：包括起始年、目标年和基准年 2.5 目标达成机制 | S3: 1) 指标与目标 建立一套指标与目标，以推动净零转型计划的执行，并监控短期、中期和长期的成果进展。包括专注于：1）使金融活动与实体经济净零转型保持一致；2）执行转型计划；3）衡量客户与投资组合温室气体排放变化的指标与目标。 ・明确定义将跨类别追踪的指标：实体经济转型（通过四大融资策略）、计划执行、已融资排放，包括每项的范围与覆盖度 ・定量与定性的中期和最终目标 ・基准线、当前及预计的已融资温室气体足迹，包括范围 1、2 和 3 排放，以及排放中和里程碑，说明如何计划在 2050 年前通过高质量、永久性清除来最终中和任何剩余排放 ・假设的方法论与范围，概述目标所依据的相关科学 ・为目标背景提供信息的重大决策或选择 ・针对明确的投资组合一致性指标的进展 ・对碳信用使用与质量的监控指标 ・指标与目标的复核及更新频率，以及过往更新记录 ・在实体经济转型与已融资排放中使用行业路径设定目标 | T3: 来源：公开信息 该公司发布的《2030年前碳达峰行动方案》 | U3: 来源：24年可持续发展报告 2030 年前实现“碳达峰”，2030 年前吨钢碳排放强度较基准年（2021 年）下降 5%。到 2035 年具备降碳 20% 的技术能力。 | V3: 碳达峰目标作为企业转型承诺的具体节点，能够反映企业是否将减排承诺与国家政策时间表对齐，在政策框架中与碳中和目标共同构成转型目标体系的基础层。建议与碳中和目标合并评价，综合反映企业在分阶段减排目标设置上的完整性与科学性。
C4: 其他环境目标 | D4: 指除碳达峰 / 碳中和目标之外，用于支撑低碳转型路径落地的能效、资源、污染与过程优化类目标。 可识别目标类型包括但不限于： 1. 能效提升（如吨钢综合能耗下降） 2. 能源结构优化（如清洁电力占比、余热利用） 3. 污染物减排（SO₂ / NOx / PM / VOCs） 4. 水资源管理（吨钢取水量、回用率） 5. 资源循环与废弃物（废钢比、固废利用率） 6. 工艺与流程优化（短流程占比、关键工序效率） | E4: 无重大损害原则：转型金融支持的经济活动或企业，应当对污染防控、资源节约和生态保护等其他环境目标无重大损害 | G4: 第四十条 企业应当披露与特定业务模式、活动或者表明企业所处行业的其他共同特征相关的行业特定指标。企业在确定披露的行业特定指标时，应当充分考虑相关法律法规和政策的要求（如行业应用指南），以及行业内其他企业的披露惯例。 | I4: 第三十条（污染防治）、第三十五条（能源利用）、第三十六条（水资源利用）、第三十七条（循环经济）等条款要求披露相关目标、措施及成效。 | L4: 1. 为能源投资和森林砍伐政策制定明确的指令，并适当披露这些指令； | N4: 如果企业制定关于气候变化政策或承诺陈述，承诺会解决相关问题，或减少或避免气候变化的影响（如减少碳排放或提高能源效率） | Q4: 4. 指标与目标 4.1 治理、业务与运营指标及目标 主体应当披露其为推动和监控转型计划战略愿景进展所使用的治理、参与、业务与运营指标及目标，并至少每年针对这些指标和目标进行一次报告。 披露建议…… 4.2 财务指标与目标 主体应当披露与其业务、行业及战略相关的财务指标与目标，这些指标和目标用于推动和监控转型计划战略愿景的进展，并至少每年针对这些指标和目标进行一次报告。 披露建议…… | T4: 来源：24年可持续发展报告 吨钢综合能耗、污染物减排、能源结构优化、水资源管理、资源循环与废弃物、工艺与流程优化 | U4: 来源：24年可持续发展报告 能源管理目标（吨钢综合能耗、能源消费用量、绿电装机容量） | V4: 其他环境目标（如能效提升、污染物减排、水资源管理等）虽与低碳转型并非直接关联，但在主要转型金融、气候政策及行业转型路径框架中，通常以协同目标、约束条件或补充要求的形式出现，可辅助反映企业的环境治理水平和综合可持续发展能力。因此暂作为可选指标纳入转型绩效评价体系，用于补充说明企业的综合环境表现。
B5: 战略和规划 | C5: 转型规划 | D5: 企业制定明确的转型路线图、行动方案或分阶段规划 | E5: 转型主体应当制定并披露技术可行的转型计划，主要内容和要求包括：（1）对照短、中、长期碳减排目标，明确每个阶段的转型技术路径，该技术路径应当具有可行性和先进性；（2）明确每个阶段的工作计划及重点工作任务；（3）测算每个阶段转型工作的碳减排效果。 | G5: 第十二条（四）企业已有的气候转型计划，包括制定转型计划时使用的关键假设和依据。 | H5: 一（一）2.有整体转型方案。方案应遵循以下原则：二是有清晰可行的技术路径。技术路径应当具有可行性，要遵循先进性原则、无重大损害原则和避免“碳锁定”原则'。 | I5: 第二十三条 披露主体应当披露为应对气候相关风险和机遇的转型计划、措施及其进展，包括但不限于下列内容： （一）公司为应对气候相关风险和机遇而对当前和未来战略、商业模式和资源分配进行调整的情况；（二）公司已经或者计划为直接或间接应对气候相关风险和机遇所采取的改进生产工艺、更新设备等措施；（三）公司为应对气候相关风险和机遇所制定的转型计划，及制定该计划所依赖的基本假设；（四）公司为实施转型计划提供的资源；（五）公司实施转型计划的进展情况。 | L5: 治理和战略： 5. 转型计划的实施； 7. 将转型计划纳入投资和投资组合经理的任务和目标； 4. 审查转型计划中假设和依赖性的影响，包括假设未实现时的影响； 6. 更新将影响转型计划有效性的支持性财务计划、预算和相关财务目标。 | M5: CTF：要素1.发行人的气候转型战略和治理：气候过渡主要关注发行人减排温室气体（GHG）策略、承诺和实践的可信度。气候转型策略应清晰传达并提供详细信息，说明发行人打算如何随着时间调整其商业模式以实现《巴黎协定》的目标。 CTB：发行人需满足以下要求： 制定发行人层面的可持续发展和/或转型战略，合格气候转型项目须对该战略形成支撑，且相关披露文件应尽量与《气候转型金融手册》四大核心要素保持一致； 若气候转型项目与化石燃料基础设施或活动存在重大关联，且未被涵盖入前述分类目录、脱碳路径与路线图或政策框架，则还可以具备以下内容：活动/资产层面的转型计划； 承诺在符合可验证情景的时间框架内，退役/逐步淘汰相关资产，或转向低碳替代方案；关于前瞻性指标的年度报告，包括关键里程碑、最后期限及其外部核验情况； | N5: 企业阐述在转型计划中为达到中长期目标所使用的抵消和/或负排放技术的种类及作用。 企业明确承诺有时限地逐步淘汰对碳密集型资产或产品的投资（而不是只包括提取现有资产的承诺。 1.5摄氏度 与《巴黎协定》的总体目标一致，即“与工业化前水平相比，将全球平均气温升幅控制在低于2°C的水平，并努力将气温升幅限制1.5°C”。 该场景与将全球平均气温上升限制在1.5°C，可能性为50%的碳预算一致。 低于2摄氏度 符合《巴黎协定》限制全球变暖的总体目标，尽管处于目标范围的中间。 该场景与将全球平均气温上升限制在1.65°C，可能性为50%的碳预算一致。 国家承诺 建立在国际能源署2020年既定政策情景的基础上，该情景考虑了至少到2020年年中已经实施或正在制定的政策，具体取决于行业； 目前这一总量不足以使世界走上将升温限制在2°C的道路。 该场景与将全球平均气温上升限制在2100年的2.6°C，可能性为50%的碳预算一致。 | O5: 早期转型 ・2050 年目标：削减范围 1 和 2 绝对排放量（指标 1.1） ・2030 年目标：削减范围 1 和 2 绝对排放量（指标 1.4） 进展中转型 满足早期转型所有前提条件，且： ・2050 年目标：实质性削减（至少）范围 1 和 2 排放量（指标 1.1） ・目标：削减范围 3 绝对排放量（到 2030 年和 2050 年）或削减排放强度（到 2030 年和 2050 年）（指标 1.2、1.5 或 1.3、1.6） ・承诺将年度投资的一部分用于转型（指标 3.3） 充分转型 满足进展中转型所有前提条件，且： ・目标：到 2050 年范围 1 和 2 实现净零，并设定可量化且具雄心的范围 3 减排目标（指标 1.1、1.2、1.3） ・短期内展示范围 1 和 2 减排进展（指标 2.4） ・展示转型收入进展（至少部分收入来自转型活动或产品）（指标 3.5 或 3.6） 先进转型 满足充分转型所有前提条件，且： ・将年度转型投资的实质性部分投向绿色活动、服务或产品（指标 3.3、3.4） ・展示进一步转型进展（至少部分收入来自绿色活动或产品）（指标 3.6） ・目标：到 2050 年所有范围实现净零，且可信的愿景覆盖相关实质性边界（指标 1.1、1.2、1.3） ・展示所有范围的减排进展（指标 2.1、2.2、2.3、2.4、2.5、2.6） 转型领导者 满足先进转型所有前提条件，且： ・将年度投资的绝大部分投向绿色活动、服务或产品（指标 3.3、3.4） ・展示实质性转型进展（收入中很大一部分来自绿色活动或产品）（指标 3.6） ・实现所有范围的深度减排（指标 2.1、2.2、2.3、2.4、2.5、2.6） | P5: （4）日期：转型计划规定了计划达成的目标，包括在计划的时间范围内应达成的目标（例如，计划时间路线图）。 （2）计划假设：转型计划中描述相关假设，尤其是围绕转型路径的不确定性和实施挑战的假设。这些假设应该与组织财务情况、资本支出和投资决策方面使用的假设保持一致。 （4）行动计划：概述短期和中期战略和行动计划，并描述相关行动如何解决温室气体排放，包括减少气候相关风险和增加气候相关机遇的计划举措。 （5）财务计划：转型计划描述了支持性财务计划、预算和相关财务目标（例如，支持脱碳战略的资本和其他支出金额）。 | Q5: 1.1 战略愿景 主体应当披露其转型计划中的战略愿景。这包括主体在向低温室气体排放、气候韧性经济转型过程中，为响应并推动转型而设定的目标与优先事项，同时说明主体将如何以把握机遇、避免对利益相关方和社会造成不利影响、保护自然环境的方式来追求这些目标和优先事项。 披露建议 作为此部分的内容，主体应当披露： a. 其目标与优先事项： i. 旨在减少其运营或价值链中范围 1、范围 2 和范围 3 温室气体排放的目标与优先事项 ii. 旨在增强其对气候变化的适应能力，并应对向低温室气体排放、气候韧性经济转型所带来的风险与机遇的目标与优先事项 iii. 旨在利用其可用的杠杆与能力，嵌入并加速向低温室气体排放、气候韧性经济转型的目标与优先事项 b. 其是否以及如何识别、评估并考量转型计划对利益相关方（如员工、价值链合作伙伴、客户、社会（如当地社区）、经济和自然环境）的影响与依赖关系，以及这些影响与依赖关系在整个价值链中可能引发的可持续性相关风险与机遇 c. 其在多大程度上考量并遵循了外部要求、承诺、基于科学的目标、转型路径、路线图或情景， 1.2 商业模式与价值链 主体应当披露其战略愿景对当前及预期商业模式与价值链的影响描述。 披露建议 作为此部分的内容，主体应当披露： a. 其商业模式与价值链当前及预期的战略变化概览（详见第 2 部分《实施策略》和第 3 部分《参与策略》） b. 预期发生这些变化的时间范围 1.3 关键假设与外部因素 主体应当披露其为实现转型计划的战略愿景所做出的关键假设，以及所依赖的外部因素。 | R5: 3 主体应当披露：为实现其计划或目标所需的活动与投资，以及任何可能影响这些计划或目标达成的风险或限制因素。 4 主体应当讨论：其战略、计划或减排目标的适用范围，例如这些目标是否针对不同业务单元、地区或排放源而有所差异。 5 主体应当讨论：其战略、计划或减排目标是否与限排或排放报告计划 / 法规相关联，例如欧盟排放交易体系（EU ETS）、魁北克总量控制与交易体系、加州总量控制与交易计划，包括地区、国家、国际或州级层面的相关计划。 6 战略、计划或减排目标的披露范围：应仅限于报告期内正在进行（活跃）或已完成的活动。 | S5: 活动和决策过程 将金融机构的净零目标与优先事项嵌入其核心评估与决策工具及流程中，以支持其净零承诺。这适用于自上而下的监督架构与自下而上的工具与行动。 ・描述转型战略如何嵌入决策流程、工具与政策中 ・核心决策流程的重大变化摘要 ・为决策流程变化提供背景的重大事件或决策 | T5: 来源：24年可持续发展报告 中国宝武和宝钢股份碳中和技术路线图 | U5: 来源：2024年可持续发展报告 中信泰富特钢碳中和路径：绿色技术、绿色产品、绿色协同 公司为实现经济增长与能源资源使用高质量均衡发展，制定了于 2030 年前实现“碳达峰”，2060 年前实现“碳中和”的目标， 并设立了阶段性计划...... | V5: 转型规划能够体现企业是否将低碳转型系统性地纳入中长期发展战略，是目标向实施转化的重要承接环节，也是国内外主流政策框架中的普遍要求。企业通常能够披露转型路线图、阶段性目标及主要行动措施，具备一定的评价区分度，建议作为核心指标予以保留。
C6: 其他战略 | D6: 企业如尚未制定专门的转型规划，是否已建立低碳与可持续发展相关的其他制度与行动框架 | I6: 第十二条 披露主体应当建立健全公司治理结构和内部制度，确保公司相关内部机构具备足够的专业能力并有效履行可持续发展相关影响、风险和机遇的识别、评估、管理、监督等职能。 第十五条 披露主体应当披露可持续发展相关影响、风险和机遇对公司战略和决策的影响。 | S6: 政策和条件 制定行业政策：针对动力煤、石油和天然气，以及森林砍伐等高优先级行业制定政策和条件；覆盖其他高排放或对气候有害的行业，以符合机构的净零目标和优先事项 | U6: 来源：2024年可持续发展报告 绿色低碳三年行动计划（2023—2025 年） | V6: "其他战略"口径相对宽泛，主要用于覆盖尚未制定专项转型规划的企业是否已建立相关低碳治理与行动框架，发挥一定的补偿作用。建议将该指标的评分权重设置低于"转型规划"，以强化对明确指向低碳转型的专项规划的评价重心。亦可视后续企业评分取样情况，决定是否作为可选指标纳入体系。
A7: 实施举措与保障 | B7: 转型举措 | C7: 自身减排措施 | D7: 企业为实现低碳转型与应对气候变化，当前已实施或计划实施的关键减排与转型措施，包括发生在企业自身运营与资产层面的直接措施。 | E7: 转型主体应当制定并披露技术可行的转型计划，主要内容和要求包括：(1)对照短、中、长期碳减排目标，明确每个阶段的转型技术路径，该技术路径应当具有可行性和先进性； (2)明确每个阶段的工作计划及重点工作任务； | G7: 第十二条（二）当前和计划采取的用于减缓和适应气候变化的直接措施（如节能产品认证、碳标识认证，改变生产工艺或者设备、搬迁设施、调整劳动力结构以及改变产品规格等）。 | I7: 第二十七条 披露主体应当披露温室气体减排实践的相关信息，包括参与各项减排机制的情况、减排目标、减排措施（如管理措施、资金投入、技术开发等）及其成效等。 | L7: 3. 将净零目标与标准指标一起纳入投资组合建设。理想情况下，额外的调整目标应涵盖脱碳和气候解决方案； 5. 监测调整目标的实现情况，包括组合碳强度和气候解决方案的分配情况； | N7: 问题19：企业是否将减排战略和为达到标所采取的行动的影响进行量化？ 企业量化了减排战略的关键因素，包括范围3排放，并且披露每一项行动的量化贡献，即该行动将占温室气体总目标的大致比例。 | O7: 钢铁行业调整系数说明——钢（条目3）：若主体用相对新的（<25 年）的高炉 - 转炉（BF-BOF）产能替换为废钢基电弧炉（EAF）产能，加 1 分，采用正向修正。 钢铁行业调整系数说明——钢（条目4）：若主体投资新建无碳捕集的高炉 - 转炉（BF-BOF）产能，采用否定性修饰语。 钢铁行业调整系数说明——钢（条目5）：若减排量中使用抵消额度占比超过 10%，采用否定性修饰语。 | Q7: 2. 实施策略 2.1 业务运营 主体应当披露其为实现转型计划的战略愿景，在业务运营中已采取或计划采取的短期、中期和长期行动相关信息。 披露建议 作为此部分的内容，主体应当披露： a. 当前及预期行动的相关信息（包括时间线），涉及以下事项： i. 生产流程或设备 ii. 劳动力调整 iii. 供应链与采购 b. 与主体设施及其他实物资产相关的当前及预期变化，例如： i. 办公场所与运营地点 ii. 温室气体高排放资产的负责任退役或逐步淘汰 iii. 应对气候变化风险所涉及的资产管理 iv. 向低温室气体排放、气候韧性经济转型过程中可能受影响的长期资产管理 c. 各项行动对实现其战略愿景的预期主要贡献 2.2 产品与服务 主体应当披露其为实现转型计划的战略愿景，已采取或计划采取的短期、中期和长期行动相关信息，以改变其产品与服务组合。 披露建议 作为此部分的内容，主体应当披露： a. 当前及预期行动的相关信息（包括时间线），以改变其提供或促成的产品与服务组合（例如，通过特许经营、融资或承保活动） b. 用于对此部分下的产品与服务进行分类的任何基础分类体系、工具、方法或定义 c. 各项行动对实现其战略愿景的预期主要贡献 | S7: 产品及服务 利用现有及新产品与服务，支持并提升客户与投资组合公司的转型努力，使其符合 1.5℃净零排放路径。包括加速并扩大实体经济中的净零转型，提供转型相关的教育与建议，并按照机构的净零转型战略支持投资组合脱碳。 ・描述转型战略如何嵌入产品与服务设计中，以最大化机遇 ・与转型目标一致的产品与服务摘要 ・核心产品与服务的任何重大变化摘要 | T7: 来源：24年可持续发展报告 | U7: 来源：24年可持续发展报告 | V7: 前期设置"自身减排措施"和"供应链减排措施"两个指标，希望从企业内部运营和外部供应链两个维度分别评价具体减排行动。但在实际梳理企业报告的过程中发现，上述指标内容与"转型规划"及"转型表现"存在较大内容重叠，独立设置将导致评价体系冗余。因此，建议将相关内容统一整合至"转型规划"指标中，通过综合评价系统呈现企业在自身运营和供应链层面的减排措施，以提高指标体系的简洁性与内部一致性。
C8: 供应链减排措施 | D8: 企业为实现低碳转型与应对气候变化，当前已实施或计划实施的关键减排与转型措施，包括通过价值链协同实现的间接措施。 | E8: 1.转型主体应当对照国家碳达峰碳中和目标，制定并披露科学合理的碳减排目标，主要内容和要求包括：(3）温室气体排放核算范围至少包括范围一和范围二的温室气体排放；条件成熟时，酌情将范围三的温室气体排放纳入核算范围。 转型主体应当制定并披露技术可行的转型计划，主要内容和要求包括：(1)对照短、中、长期碳减排目标，明确每个阶段的转型技术路径，该技术路径应当具有可行性和先进性；(2)明确每个阶段的工作计划及重点工作任务； | G8: 第十二条（三）当前和计划采取的用于减缓和适应气候变化的间接措施（如与客户、供应链合作等） | I8: 第四十五条 披露主体应当披露报告期内加强供应链风险管理、保障供应链安全稳定的情况，包括但不限于下列内容： （一）供应链风险管理的基本情况，包括但不限于公司制定的供应链风险管理目标及具体计划、供应链风险应对机制、措施及实施效果；（二）通过并购重组、科技创新等保障自身供应链安全、强化供应链优势等方面的举措和积极效果。本所鼓励披露主体披露加强供应链管理、促进供应链可持续发展的行动和举措。 | L8: 参与监管机构行业倡议，制定自愿和强制性的转型计划标准和其他披露，如与巴黎协定一致的账户； 参与投资者行业网络协会，以提高有关《巴黎协定》目标基准投资组合的知识； 2. 与现有和潜在的资产管理者接触，鼓励管理者提供战略和产品，以实现资产所有者的净零投资目标； 3. 与现有和潜在客户接触，鼓励采用净零投资战略和产品，提供研究和分析，以支持气候风险评估和净零投资； 4. 促进跨行业企业转型计划的披露，例如根据IIGCC的转型计划行业中性指南和涵盖高影响力行业的净零标准； 5. 让私人数据供应商参与进来，以确保评估与气候行动100+《净零公司基准》的最新详细指标指南中的一致标准一致； 6. 与私人数据供应商合作，确保范围3排放数据详细说明评估中使用的类别及其准确性； 7. 参与投资者网络的活动，促进与净零投资相关的知识创造； 8. 表达与资产类别一致性标准相关的预期（例如，债券发行前）； 9. 与指数提供商合作，提供更符合净零的基准； 10. 与债券指数提供商接触，这些指数可能会无意中迫使投资者购买新债券，而不考虑气候影响； | Q8: 3. 参与策略 3.1 价值链参与 主体应当披露其为实现转型计划的战略愿景，正在或计划与价值链中其他主体开展的参与活动相关信息。 披露建议 作为此部分的内容，主体应当披露： a. 解释其如何优先安排参与活动，以最大程度地推动实现转型计划的战略愿景；此部分可参考在 1.3《关键假设与外部因素》中披露的关键假设和外部因素 b. 描述当前及计划的参与活动；对于金融服务主体，这可能包括与被投公司、贷款客户及相关金融市场中介的互动，以及相关的治理活动 c. 说明当参与活动未能带来预期变化时，所采用的升级处理流程或判定标准 d. 各项活动对实现其战略愿景的预期主要贡献 | R8: 供应链管理流程描述；讨论因环境和社会问题引起的铁矿石或焦煤采购风险的管理流程。—— 1 企业应披露有关其供应链中管理环境和社会风险的政策和程序的信息。讨论其管理供应链中环境和社会风险的政策和程序。可能会影响采购的铁矿石或焦煤供应链中存在的环境和社会风险。 2 企业应披露其采购原材料中经第三方验证的与环境或社会问题相关的供应链认证或认可的比例（按成本计算） | S8: 1) 客户与投资组合公司：积极且建设性地向客户和投资组合公司提供反馈与支持，鼓励其制定与净零目标一致的转型战略、计划与进展，并建立当参与无效时的升级处理框架及相应后果。 ・参与目标与方法的摘要，包括客户与投资组合公司的优先级排序、升级处理流程及时间线 ・参与活动的进展详情 ・如适用，描述与公司就其受控淘汰计划设计及进展的沟通情况，以及达成的关键指标 2) 行业：积极与行业同行进行接触，适时交流转型专业知识，共同应对行业挑战，并代表金融部门向外部利益相关方（如客户与政府）进行连贯一致的发声。 ・参与目标与方法的摘要，包括客户与投资组合公司的优先级排序、升级处理流程及时间线 ・参与活动的进展详情 ・如适用，描述与公司就其受控淘汰计划设计及进展的沟通情况，以及达成的关键指标 3) 政府与公共部门：直接与间接的游说及公共部门参与应保持一致，以支持有序向净零转型，并在适当时鼓励客户与投资组合公司的游说及倡导工作与机构自身的净零目标保持一致。 ・参与活动的摘要，包括议题与受众（如适用，使间接游说活动与净零转型保持一致的努力） ・参与活动如何被评估及与净零转型保持一致的概述 ・参与活动的进展详情 | T8: 来源：24年可持续发展报告 公司根据已发布的降碳行动方案，制定了供应链减碳规划，并严格督促落实，形成了“量化、评估、减碳”的供应链低碳发展路径。通过这一系列举措，宝钢股份携手产业链上下游企业，为应对全球气候变化做出实质性贡献。 ·我们累计引导 1,500 余家供应商开展产品碳核算，累计与 50多家重点供应商开展减碳技术交流，发布产品碳核算报告超过 5,000 份，为减碳奠定坚实基础 ·基于已量化的工业品实际碳足迹数据，我们开展碳足迹数据“评估”。我们通过横向评估（同一产品不同供应商）和纵向评估（同一供应商同一产品不同年份）两个维度开展碳数据评估，持续发挥工业品碳数据的实际应用价值 ·在持续推进“量化”与“评估”工作的基础上，我们成功引导1,000 余家供应商提升低碳管理 能 力，并助力100余家重点供应商的500多个工业品实际碳排放量较上一年度下降超过5% | U8: 来源：24年可持续发展报告 公司已制定并实施了严格的采购及供应商管理规范，包括《供应商管理制度》《统购物资集中购销管理办法》《统购物资 招标管理细则》等制度，以确保采购流程的合规性与高效性。公司要求所有供应商签署并执行《供应商行为准则》，在管 理中将 ESG 行动列为对供应商的评价加分项，并就人权与劳工权益、环境保护、安全生产以及隐私保护等关键议题向供应 商提出明确要求，旨在有效降低供应链中的 ESG 相关风险。 公司积极响应国家“双碳”战略目标，致力于推动供应链向节能低碳转型。公司持续采购获得环境标志产品认证、节能产品认证或国家权威机构认可的其他认证的节能环保产品，并严格禁止采购“高污染、高环境风险”类产品，旨在为推进环境友好型社会的构建贡献力量。2024 年度，公司共有合格供应商 371 家。 公司持续优化供应链生态，促进产业链上下游企业绿色发展，积极履行国有企业社会责任，推动全产业链低碳发展。本年度，公司在《采购中心供应商管理办法》中将碳排放管理纳入原材料供应商准入、年审考评机制中，致力于将供应链管理与环保要求相融合，响应公司绿色低碳战略。公司要求参与合金类产品招标的供应商原则上需提交碳足迹数据，并广泛鼓励所有供应商采取措施以降低碳排放并提升能源利用效率。 本年度，公司召开首次绿色供应链碳核算报告交付评审会，签署《产品碳核算服务验收单》，完成对 11 家大宗物资供应商的评估，并发布 14 份详尽的正式报告。公司已面向相关供应商推进 626 项产品碳足迹核算报告收集工作，旨在全面评估上游供应商的碳排放水平，为制定碳减排策略提供可靠数据支持，也为构建公司绿色供应链数据库奠定坚实基础。 公司与供应商建立了良好的绿色低碳交流与合作机制。本年度，公司在绿色供应链管理方面积极行动，成功举办两场绿色供应链管理宣贯会，针对提升供应商管理水平与绿色采购效率等两个核心要点，进行了深入且全面的探讨。公司邀请知名专家对供应商进行碳排放意识培养与指导，传达公司在采购策略上的最新绿色理念。此外，针对供应商在准入及执行阶段可能遭遇的环保风险，提出了一系列针对性的建议，旨在促进上下游供应链合作共赢，推动绿色协同发展实现 | V8: 供应链减排措施与自身减排措施同属转型规划的实施行动层面，两者均偏向描述性披露，难以独立进行定量评价，且内容易与"转型规划"评价产生重叠。因此，建议与"自身减排措施"同步删除，将相关内容统一整合至"转型规划"模块中进行综合评价，以保持指标体系的简洁性。
B9: 治理 | C9: 治理架构 | D9: 企业围绕低碳/绿色/可持续/转型/ESG议题建立的治理层级完整性与权责清晰度 | E9: 4.转型主体应当制定并披露切实可行的治理计划，主要内容和要求包括：(1）落实转型计划的治理模式和实施方案，例如董事会和高管责任安排、内部分工与激励计划、温室气体排放监测与报告体系、信息披露机制等； | G9: 第六条：企业应当披露负责监督气候相关风险和机遇的治理机构（包括董事会及其下设委员会或者其他类似机构）或者人员的情况。 | H9: 一（一）3.四是有落实转型方案的治理模式和实施方案。 | I9: 第十二条 披露主体应当建立健全公司治理结构和内部制度，确保公司相关内部机构具备足够的专业能力并有效履行可持续发展相关影响、风险和机遇的识别、评估、管理、监督等职能。 | L9: 2. 建立一个内部系统，定期监督实施情况； 3. 净零战略实现净零目标的能力（包括审查和更新净零目标、战略和指标）； 4. 制定计划以确保整个组织拥有适当的资源、技能和能力，以有效实施净零战略； 5. 将净零目标和战略以及目标纳入薪酬激励措施，视情况而定，并小心避免意外后果； 6. 制定向董事会、高级管理层和外部利益相关者报告净零目标、战略和目标的进度报告计划，包括预期和非预期结果； | M9: CTF：要素1.发行人的气候转型战略和治理：推荐信息和指标：对发行人气候转型策略的明确监管和治理，包括管理层/董事会层级的问责 | N9: 提供清晰的董事会或董事委员会对气候变化监督的证据，或有在董事会层面任命负责气候变化的人员或职位。 | P9: 治理： （1）审批：董事会或者相关董事会委员会审批转型计划和气候相关目 标。 （2）监督：董事会或者相关董事委员会监督转型计划的实施情况。 （3）责任：高级管理层负责执行转型计划，相关人员有足够权力和资 源确保转型计划的有效执行。 （4）激励措施：薪酬和其他激励措施应与组织的气候目标保持一致。 （5）报告：定期披露低碳转型现状报告。 （6）审查：组织定期审查和更新自身计划、活动、指标和目标。 （7）透明度：组织向外部利益相关方报告转型计划目标和绩效，包括 财务、目标完成情况以及对组织业务造成的影响等。 （8）保证：组织的报告受到独立审查或者第三方保证的约束。 | Q9: 5. 治理 5.1 董事会监督与报告 主体应当披露关于负责监督转型计划的治理机构（可包括董事会、委员会或等效治理机构）或个人的相关信息。 披露建议 作为此部分的内容，主体应明确该治理机构或个人，并披露： a. 其对转型计划及其战略愿景的审核与批准机制，包括对任何变更、更新及报告的监督安排 b. 转型计划的相关责任如何体现在该治理机构或个人的职权范围、授权、角色描述及其他相关政策中 c. 该治理机构或个人如何确定是否具备或是否需要培养监督转型计划的适当技能与能力 d. 该治理机构或个人获取转型计划相关信息的方式与频率 e. 该治理机构或个人在监督主体战略、重大转型决策及其风险管理流程与相关政策时，如何纳入转型计划的考量，包括是否已考虑转型计划相关的权衡取舍 f. 该治理机构或个人如何监督转型计划中目标的设定，以及对这些目标和转型计划更广泛战略愿景的进展情况进行监控 5.2 角色、责任与问责 主体应当披露管理层在转型计划的治理流程、控制与程序中的监督、管理和履职相关信息，以及这些内容如何嵌入主体更广泛的控制、复核与问责机制中。 披露建议 作为此部分的内容，主体应当披露： a. 负责执行监督与交付转型计划的管理机构或个人的身份 b. 5.2.a 中所述机构或个人在定义转型计划的战略愿景、设定目标及监控进展方面的角色 c. 对 5.2.a 中所述机构或个人的监督机制 d. 5.2.a 中所述机构或个人是否使用控制措施与程序来支持转型计划的监督，并确保所披露信息的可靠性；如果是，主体应当披露这些控制措施与程序如何与其他内部职能整合，以及转型计划的哪些内容接受外部鉴证或核查，包括鉴证或核查的性质 e. 转型计划是否需要经过股东批准，包括通过股东投票的方式 5.4 激励与薪酬 主体应当披露其如何或将如何使激励与薪酬结构与转型计划的战略愿景保持一致的相关信息。 披露建议 作为此部分的内容，主体应当披露： a. 说明其高管激励与薪酬结构是否与转型计划的战略愿景保持一致，可包含以下信息： i. 所采用的指标 ii. 该指标是否纳入短期及 / 或长期激励计划 iii. 高管激励计划中，转型计划相关指标的典型权重占比 iv. 与转型计划相关指标挂钩的高管薪酬占总薪酬的比例 b. 说明全公司范围内的激励与薪酬结构是否及如何与转型计划的战略愿景保持一致，包括其采用的方式是否与 5.4.a 保持一致，或是针对特定岗位或角色采取了差异化的方式 | S9: 1) 角色、责任与薪酬：为董事会或战略监督机构及高级管理层明确角色，确保其对净零目标拥有所有权、监督权与责任。为转型计划的设计与交付各方面指派合适的人员与团队。尽可能为所有角色使用薪酬激励。定期复核转型计划，以确保纳入重大更新与进展，将挑战视为修正方向的机会，并妥善管理实施风险。 ・与净零转型计划相关的审批、监督及报告的治理结构与流程 ・明确转型计划执行责任与问责机制的政策，以及相关的授权 ・实施或修订政策、产品与服务所需的资源 ・与净零转型计划目标、优先事项、战略及目标挂钩的激励与薪酬方法 ・任何独立复核或第三方鉴证的结果与成果 | T9: 来源：24年可持续发展报告 宝钢股份制定<<ESG工作管理制度>>等管理制度 -2 成立了以董事会为领导主体，战略、风险及 ESG 委员会为核心，ESG 工作小组为执行落地主力的自上而下多层次管理架构-2，--2，-2 | U9: 来源：24年可持续发展报告 公司制定了《环境、社会及管治工作管理办法》-2 公司构建董事会，战略、风险及ESG 委员会，ESG 协同管理工作组，ESG 推进工作组四级 ESG 管理模式，明晰各单位工 作职责，搭建长效 ESG 工作机制，有力保障公司中长期战略目标的落地实施，为公司的可持续发展筑牢根基。 公司双碳管理体系下设 8 个职能工作组，包括低碳战略规划组、低碳技术研用组、低碳产品与标准创新组、节能降碳与碳 核查组、绿色供应链建设组、碳资产管理与绿色金融组、低碳人才培养组和低碳品牌宣传组。各子公司在双碳领导小组的 指导下，积极开展当地的气候变化相关工作。 | V9: 治理架构反映企业是否建立了与低碳转型相关的决策、执行与监督机制，是转型得以持续推进的重要保障条件。企业通常能够披露董事会、管理层职责安排及相关委员会设置情况，具备一定的可比性，且在国内外主流政策框架中均有明确要求，建议作为实施保障维度的基础性指标予以保留。
C10: 薪酬激励 | D10: ESG/可持续发展/低碳/转型目标是否通过绩效与薪酬机制转化为真实的管理激励与约束 | E10: 4.转型主体应当制定并披露切实可行的治理计划，主要内容和要求包括：(1）落实转型计划的治理模式和实施方案，例如董事会和高管责任安排、内部分工与激励计划、温室气体排放监测与报告体系、信息披露机制等； | G10: 第三十九条 企业应当披露在决定高级管理人员薪酬时是否以及如何考虑气候相关因素。 | L10: 5. 将净零目标和战略以及目标纳入薪酬激励措施，视情况而定，并小心避免意外后果 | N10: 企业高管薪酬考虑了气候变化表现。 | O10: 钢铁行业调整系数说明——钢（条目6）：若高管薪酬与可量化排放相关目标挂钩（占可变薪酬总额≥20%），则可进行正向调整。 | P10: （4）激励措施：薪酬和其他激励措施应与组织的气候目标保持一致。 | Q10: 5.4 激励与薪酬 主体应当披露其如何或将如何使激励与薪酬结构与转型计划的战略愿景保持一致的相关信息。 | S10: ・与净零转型计划目标、优先事项、战略及目标挂钩的激励与薪酬方法 | T10: 来源：24年可持续发展报告 我们将董事及高级管理层的薪酬与 ESG 绩效指标相挂 钩，将安全、环境、社会、治理、合规管理等议题指标 纳入高管激励及薪酬计划中。 将 ESG 体系能力提升（安全、环境、社会、治理、 合规管理等）作为 1 个专门的指标项，纳入 2024 年度 相关经理层成员经营业绩目标。其中宝钢股份总经理“践 行绿色低碳发展，推进美丽宝钢建设”考核所占权重 15%；分管相关工作的两位副总经理“践行绿色低碳发 展，推进美丽宝钢建设”“ESG 体系能力提升”两项考 核指标分别占总权重的 15%、5%。 | U10: 来源: 24年可持续发展报告 我们根据公司实际对包括总裁在内的高级管理人员薪酬方案进行了调整，包括对本财年财务业绩的评估和对关键管理活动（如碳排放管理、水资源管理、健康与安全等可持续发展相关绩效）的评估。 此外，公司将 ESG 相关绩效表现与公司高级管理层的薪酬绩效挂钩，设立了详细的定量、定性考核标准，根据职责分工，设置 5%-40% 不同的绩效考核权重，包括环境保护、碳排放管理、节能降耗、水资源管理、健康与安全、人才梯队建设、信息安全、知识产权、客户服务、廉洁建设、ESG 信息披露和 ESG 评级等方面。公司根据考核结果对高级管理层人员采取奖惩措施，以确保公司的 ESG 核心目标和措施得到有效执行，全面提升公司可持续管理水平。 | V10: 在企业信息披露中，薪酬激励通常与综合ESG绩效或经营绩效挂钩，鲜有企业明确将薪酬激励与低碳转型目标或减排指标直接绑定。若单独设置该指标，一方面容易与ESG综合评价体系产生混淆，另一方面可比性较弱。综合考虑数据可得性与指标区分度，建议不作为独立三级指标，而将碳相关薪酬挂钩情况作为"治理架构"评价框架中的加分项，以体现企业治理的深度与约束力。
B11: 风险管理 | C11: 气候风险管理体系 | D11: 1. 全面风险嵌入（ERM化）：将气候风险由单一环保议题上升为公司级战略风险，实质性嵌入ERM及全价值链决策流程。 2. 治理架构多级化：构建“董事会—管理层—执行层”的三级或四级垂直穿透式治理架构。 3. 管控手段数智化：建设并运行“智能气候风险管理信息系统”或数字化管理平台，实现风险数据的常态化监测与可视化。 4. 责任落实绩效化：形成“目标—执行—考核—追责”闭环，并将气候/碳相关指标刚性挂钩领导班子或管理层年度经营业绩评价。 | G11: 第二十二条 企业应当披露其识别、评估、排序和监控气候相关风险的流程和相关政策。 第二十四条 企业应当披露其识别、评估、排序和监控气候相关风险和机遇的流程在多大程度上以及如何融入企业的整体风险管理流程。 | H11: 三（二）4.鼓励金融机构建立健全转型风险管理制度，明确责任和流程，探索建立风险监测及评估指标体系，对转型金融风险状况进行监测和分析，确保商业可持续与降碳目标相协同。 | I11: 第十八条 披露主体应当披露用于识别、评估及管理可持续发展相关影响、风险和机遇的流程。 （一）公司识别、评估可持续发展相关影响、风险和机遇的方法，以及评估这些影响、风险和机遇发生的可能性、大小和影响的途径； （二）公司对可持续发展相关影响、风险与机遇的优先级排序及排序标准； （三）公司监测可持续发展相关影响、风险和机遇的情况，如管理机制、具体流程等； （四）可持续发展相关影响、风险和机遇管理流程融入公司内部管理流程的情况，以及报告期内的调整情况 | L11: 6. 治理：董事会对气候风险和气候战略执行情况的监督。理事会每年至少讨论一次气候风险管理和战略。 | N11: 问题2：企业是否认识到气候变化对业务是相关风险/机遇 /企业能够证明对“气候变化对业务而言是相关风险/机遇”的认识，或如果他们将以下至少两项融入到管理实践中：Q12. 有管理气候相关风险的过程；Q14. 为减少温室气体排放设定长期定量目标；Q15. 将气候变化表现融入高管薪酬；Q16. 将气候变化风险和机会融入战略；Q17. 采取气候场景计划；Q18. 披露内部碳定价；Q19. 确保气候变化政策和其所属行业协会立场一致 问题11： 企业是否有管理气候相关风险的流程？ 企业将气候变化纳入全公司风险管理，或者他们有特定的气候相关风险管理流程。 | P11: （1）描述风险：转型计划描述了组织在向低碳经济转型过程中面临的风险。 （2）计划挑战和不确定性：转型计划描述了组织在顺利执行其转型计划过程中面临的假设、不确定性和挑战。 | R11: 供应链管理流程描述；讨论因环境和社会问题引起的铁矿石或焦煤采购风险的管理流程。—— 1 企业应披露有关其供应链中管理环境和社会风险的政策和程序的信息。讨论其管理供应链中环境和社会风险的政策和程序。可能会影响采购的铁矿石或焦煤供应链中存在的环境和社会风险。 2 企业应披露其采购原材料中经第三方验证的与环境或社会问题相关的供应链认证或认可的比例（按成本计算） | T11: 来源：24年可持续发展报告 我们设立战略、风险及 ESG 委员会，碳中和推进委员会和碳中和办公室，相关管理人员具备气候相关战略及风险管理能力。我们建立了定期的汇报机制，确保治理架构各层级分工明确。-2 我们对未来不同情景下可能发生的气候变化状况进行预测与分析，评估其对宝钢股份的影响状况，并基于分析结果，明确应对气候变化的战略目标及路径。我们定期回顾更新应 对气候变化战略目标及路径，确保其有效性。-2 宝钢股份建立了完整的气候变化风险管理流程，并将气候风险管理融入企业风险管理流程，确保在面对气候变化带来的挑战时能够做出及时有效的应对策略。我们将气候风险相关工作进行评估和归类，组建跨部门的项目团队，并定期对各项目进行监测评估，保障气候风险相关工作的有效性。-2 公司建立了覆盖多基地的智能化气候风险管理信息系统，不断识别气候变化带来的风险，为经营决策提供有力支持。-2 | U11: 来源: 24年可持续发展报告 为有效应对气候变化风险和机遇，公司建立了完善的气候变化管理体系，以双碳工作组织架构为基础，贯彻落实董事会制定的气候变化相关制度、战略和目标。 | V11: 气候风险管理体系反映企业对气候风险的识别、评估与应对能力，是国内外政策框架和监管要求对金融机构及重点排放行业的核心关注内容之一。企业披露以定性描述为主，但在是否建立完整体系、风险识别是否覆盖转型风险与实体风险等方面具备一定区分度，建议保留并采用定性分档评价方式。
C12: 气候相关风险和机遇 | D12: 1. 风险与机遇识别完整性：同时识别转型风险与实体风险，涵盖政策/法律、技术、市场、供应链、声誉、急性与慢性物理风险等；同时识别低碳产品、能源结构优化、政策支持等机遇。 2. 时间维度清晰性：在短期（1–2年）、中期（3–6年）、长期（7年及以上）不同时间框架下开展识别与评估。 3. 财务影响关联性：识别风险和机遇对成本、收入、投资、融资、信用风险等财务事项的影响。 4. 量化深度差异：区分定性判断、间接量化（环保投入、节能降本）与直接量化（营收变化、成本变化、溢价比例、履约成本节约等）。 | G12: 第十一条 企业在披露可合理预期会影响企业发展前景的气候相关风险和机遇时，应当：（二）针对企业识别出的每项气候相关风险，说明企业将该风险认定为气候相关物理风险还是气候相关转型风险；（三）披露这些风险和机遇对企业的业务模式和价值链的当期和预期影响，以及企业的业务模式和价值链中气候相关风险和机遇集中的领域（如特定活动、业务关系、地理区域、设施和资产类型等）；（四）针对企业识别出的每项气候相关风险和机遇，明确其可合理预期影响企业发展前景的时间范围（包括短期、中期或者长期），如何定义短期、中期和长期，以及这些定义如何与企业用于战略决策的时间范围相关联。 第十三条 企业应当披露气候相关风险和机遇的当期和预期财务影响。 | I12: 第十四条 披露主体应当识别并充分评估可能在短期、中期或长期内对公司商业模式、业务运营、发展战略、财务状况、经营成果、现金流、融资方式及成本等产生重大影响的可持续发展相关风险和机遇。 | L12: 2. 使用系统方法识别影响资产的因素，以增加气候解决方案的风险敞口并降低碳强度（例如，自定义基准、气候倾斜指数、以气候为重点的影响因素）； | M12: CTB：发行人需满足以下要求：识别、分析碳锁定风险，尽力缓解该风险，并进行披露。 | N12: 问题2：企业是否认识到气候变化对业务是相关风险/机遇 /企业能够证明对“气候变化对业务而言是相关风险/机遇”的认识， 问题15：企业是否将气候变化风险和机会融入战略中？ 详细说明企业是如何将气候变化风险和机会融入战略中的，并且披露气候变化风险和机会对财务计划的影响（运营支出、资本支出、并购、债务）。 | P12: （3）优先机遇：说明组织在向全球低碳经济转型的过程中打算如何最大限度地利用气候机遇。 | T12: 来源：24年可持续发展报告 转型风险：宝钢股份紧密结合自身业务范畴与行业现状，并针对不同排放情景假设下可能面临的风险与机遇进行分析。同时，我们评估了各类风险与机遇可能引发的财务损失或增益，据此按照低、中、高确定了风险和机遇的影响程度，并明确了影响的时间范围，目前碳定价、消费者行为转变风险较大，宝钢股份已根据市场、政策等采取举措。根据情景分析结果，我们评估并列举了 2050 年零碳排放情景（NZE）、中国钢铁行业低碳转型情景中可能会对本公司运营造成潜在影响的转型风险，并通过定量分析对比各类风险可能导致的财务金额减损 / 增加，按照低、中、高确定了风险的影响程度 实体风险：随着极端天气频率和严重程度的增加，企业的生产运营以及和生产相关的原材料数量和供应的波动性将受到影响。根据情景分析结果，我们评估并列举了 RCP4.5 和 RCP6.0 情景中可能会对本公司运营造成潜在影响的实体风险，并对比各类风险可能导致的财务金额减损 / 增加，按照低、中、高确定了风险的影响程度。 | U12: 来源：24年可持续发展报告 风险覆盖了6类，并进行了应对举措：政策和法律风险、技术风险、市场风险、声誉风险、急性物理风险、慢性物理风险 政策和法律风险应对措施：加强能源消耗、低碳政策研究，及时应对政策变化；公司已制定碳中和路线图，每年投资节能减排项目；公司积极推进碳管理数字化平台建设，持续完善申报工作流程。 技术风险应对措施：与国内外科研机构联合，加大科技研发，有序开展低碳技术研究。 市场风险应对措施：利用沿江沿海优势，深挖光伏、风电潜力，提升绿电占比，研发推广低碳产品。 声誉风险应对措施：积极回应利益相关方关于应对气候变化相关的要求；定期披露ESG报告，以回应各利益相关方关注 物理风险应对措施：制定针对极端自然灾害的应急管理方案；推进供应商的社会责任评估工作，减少供应链风险。 | V12: 气候相关风险与机遇的识别和评估是风险管理能力的重要组成部分，相关披露能够体现企业对气候议题的战略整合程度。该指标在TCFD、IFRS S2等主流框架中均有明确要求，且部分企业已开始在报告中进行具体描述。建议保留并采用定性分档评价方式，重点考察识别维度的完整性和财务影响的关联程度。
C13: 气候压力测试 | D13: 1. 开展情况：明确披露已开展气候情景分析或压力测试。 2. 情景设置特征：情景覆盖转型风险与实体风险，包含中长期时间尺度。 3. 方法论来源：参考国际或行业权威情景与框架（如 IFRS S2、IEA、IPCC、钢铁行业低碳转型情景）。 4. 结果应用：情景分析结果用于评估对经营、成本、收入、资产或融资的潜在影响，并支撑风险管理或战略判断。 | G13: 第十七条 为使可持续信息基本使用者了解企业的战略和业务模式对气候相关变化、发展和不确定性的韧性，企业应当考虑已识别的气候相关风险和机遇，使用气候相关情景分析评估其气候韧性，并披露下列信息：（一）报告日气候韧性评估的内容；（二）进行气候相关情景分析时使用的输入值信息；（三）进行气候相关情景分析时运用的关键假设；（四）进行气候相关情景分析的报告期间。 第十八条 企业应当结合其面临的气候相关风险和机遇以及进行情景分析可用的技能、能力和资源，确定其使用的气候相关情景分析方法。 第十九条 企业可以按照战略规划周期（如每三至五年）进行气候相关情景分析。如果企业并未每年进行气候相关情景分析，则企业根据第十七条（二）至（四）规定对气候相关情景分析的披露可能与上一个报告期间相同，但需每年对气候韧性进行评估，并按照第十七条（一）规定披露相关信息，以反映气候相关变化、发展或者不确定性对企业业务模式和战略的影响。 | I13: 第二十二条 披露主体应当结合所识别的气候相关风险和机遇，评估公司的战略、商业模式等对气候变化的适应性，并披露下列事项： （一）公司关于气候变化对其战略和商业模式影响的评估情况，以及应对相关影响的方法； （二）公司在评估其气候适应性时考虑的重大不确定性因素； （三）公司在短期、中期和长期内为适应气候变化调整其战略和商业模式的能力。 本所鼓励有条件的披露主体采用情景分析等方式进行气候适应性评估，并披露情景分析关键假设、分析过程等。 | L13: 1. 描述用于指导目标设定和评估公司一致性的基于科学的情景或路径，包括这些情景或路径如何满足关键参数和使用的关键假设； 1. 进行情景分析，以更新资本市场假设、资产水平风险/回报预期，并对投资组合进行压力测试； | N13: 问题16：企业是否采取气候场景计划？ 提到与商业规划相关的2摄氏度情景，或者确认已经进行与气候相关的情景分析，并且描述了一个或多个气候情景分析的商业影响。 | P13: （6）情景分析：组织使用多种气候相关情景测试转型计划和相关目标的可实现性。 | T13: 来源：24年可持续发展报告 宝钢股份遵循气候相关财务信息披露工作组（Task Force on Climate-related Financial Disclosure, 即 TCFD）的披露方 法及建议，利用情景分析模型等分析技术对气候变化趋势及其与公司运营之间的关系进行预测评估。我们参考了中国钢 铁工业协会和国际能源署（IEA）所模拟的情景，对宝钢股份进行转型风险的情景分析： 宝钢股份紧密结合自身业务范畴与行业现状，并基于公开的数据来源，包括政府间气候变化专门委员会(IPCC)和国际能源署(IEA)关于气候排放路径的评估和报告，针对不同排放情景假设下可能面临的风险与机遇进行分析。在此基础上，我们内部采用定量分析方法，确定了影响的时间范围包括短期(1年~2年)，中期(3年~6年)及长期(7年及以上)同时，我们评估了各类风险与机遇可能引发的财务损失或增益 针对气候实体风险的情景分析，我们参考了政府间气候变化专门委员会(IPCC)所制定的代表性浓度路径RCP4.5与RCP6.0情景: 根据情景分析结果，我们评估并列举了2050年零碳排放情景(NZE)、中国钢铁行业低碳转型情景中可能会对本公司运营造成潜在影响的转型风险，并通过定量分析对比各类风险可能导致的财务金额减损/增加，按照低、中、高确定了风险的影响程度。根据情景分析结果，我们评估并列举了 RCP4.5和 RCP6.0情景中可能会对本公司运营造成潜在影响的实体风险，并对比各类风险可能导致的财务金额减损/增加，按照低、中、高确定了风险的影响程度。 | U13: 无 | V13: 气候情景分析与压力测试是企业转型韧性评估的重要工具，有助于识别不同升温路径下的潜在风险与财务影响。该指标在TCFD、IFRS S2等权威框架中均被明确要求，部分领先企业已具备相关披露，但整体普及率仍有待提升。建议保留并采用定性分档评价，重点关注情景覆盖的完整性和结果的实际应用深度。
C14: 环境行政处罚（负向指标） | D14: 衡量企业在战略转型期（如前/后3年）因环境违法行为受到地方监管部门行政处罚的严重程度。 | E14: 无重大损害原则：转型金融支持的经济活动或企业，应当对污染防控、资源节约和生态保护等其他环境目标无重大损害 | G14: 第四条 企业还应当披露本准则第二章至第五章未涵盖的重要的气候相关影响信息。 气候相关影响包括企业活动对气候变化产生的实际或潜在影响，环境行政处罚可能属于此类影响的负面表现。 | H14: 二（一）4.做好转型信息披露。企业参照《钢铁企业转型信息披露模板》(附5)，在贷款存续期内按年度向提供融资支持的金融机构履行信息披露义务。内容包括但不限于：转型方案落实情况、转型融资使用情况、转型关键绩效指标完成情况、是否有重大环境违法违规行为、第三方机构跟踪评估意见等。企业碳排放相关数据以温室气体排放核查报告为准。 | I14: 第三十条（五）报告期内因污染物排放受到重大行政处罚或被追究刑事责任的情况，以及公司环境监测方案和风险管理措施是否存在重大缺陷。 | J14: 基础指标（三）环境保护。符合生态环境分区管控、环境影响评价、环境保护设施“三同时”、环境保护竣工验收等要求。依法申领排污许可证，履行依证排污责任，落实重点污染物排放总量控制要求。2026 年起完成全流程超低排放改造并公示。 | T14: 来源：各地生态环境局官网（行政处罚公告栏） | U14: 来源：各地生态环境局官网（行政处罚公告栏） | V14: 环境行政处罚属于转型过程中的合规约束类负向指标，能够从风险管控角度反映企业在监管合规方面的表现。相关信息公开性强、可核验性高，具有较强的约束意义。建议至少将环境行政处罚作为必选负向指标予以保留；安全生产行政处罚和失信事件管理因与转型主题直接关联度相对较低，可作为可选指标纳入体系，综合评价企业合规经营水平。
C15: 安全生产行政处罚（负向指标） | D15: 衡量企业因违反安全生产法规受到处罚或发生生产安全责任事故的严重程度 | G15: 第四条 企业还应当披露本准则第二章至第五章未涵盖的重要的气候相关影响信息。 安全生产事故可能与气候相关物理风险（如极端天气导致的安全事故）有关，或因转型措施不当引发。 | I15: 第五十条（二）职业健康与安全的基本情况，包括但不限于针对公司职业安全风险及来源的识别与评估情况，职业健康安全管理体系的建立及实施情况、相应资质认证获得情况、相关培训情况，工伤保险、安全生产责任险的投入金额及人员覆盖率，报告期内安全事故的具体情况（如有）等； | J15: 基础指标（五）安全生产。落实安全生产主体责任，遵守《冶金企业和有色金属企业安全生产规定》，配套建设安全设施、职业卫生防护设施，具备安全、职业卫生、消防竣工验收等相关手续。上年度以来未发生较大及以上生产安全事故，未发生重大及以上网络安全事件、数据安全事件。 引领指标（五）安全化。积极提升本质安全、生产安全水平，强化网络安全、数据安全管理能力。积极推进资源保障能力建设，提升铁矿、废钢/直接还原铁/镍铁等主要生产原料的保障能力。 | R15: （1）死亡人数（2）总可记录事故率（TRIR）（3）死亡率（4）未遂事故频率（NMFR）（a）直接雇员和（b）非雇员合同工 ——1 企业应分别披露（1）（a）员工和（b）非员工工人因工伤和工作相关疾病造成的死亡人数； 2 实体应分别披露（2）（1）其（a）雇员和（b）非雇员工人的工作相关伤害和疾病的总可记录事故率（TRIR）； 3 披露包括所有工人，无论其地点或就业类型如何；4 所有披露的费率应按以下方式计算：（统计数量×200,000）报告年度内所有员工的工作总小时数。 5 如果报告期内劳动力总数发生重大变化，实体应解释这些变化。 6 实体应披露以下每个员工类别的费率； 7 披露范围包括所有员工，无论员工地点或就业类型如何。 | T15: 来源：各地方应急管理局（厅/局）官网（行政处罚或事故通报栏） | U15: 来源：各地方应急管理局（厅/局）官网（行政处罚或事故通报栏） | V15: 安全生产行政处罚能够从劳工权益保护和企业安全管理角度反映企业合规水平，在转型过程中对员工影响的评价维度具有一定参考意义。但与转型绩效的直接关联度相对弱于环境行政处罚，建议作为可选负向指标纳入体系，与环境行政处罚配合使用，综合反映企业的合规经营状况。
C16: 失信事件管理（负向指标） | D16: 量化转型期企业面临的诉讼压力与现金流风险，案件常涉及合同（供应链）、劳动（安置）、金融（偿债）纠纷。 | G16: 第四条 企业还应当披露本准则第二章至第五章未涵盖的重要的气候相关影响信息。失信事件可能影响企业声誉和财务稳定性，与气候相关转型风险（如政策、法律、市场风险）相关。 | I16: 第四十六条 披露主体或者其控股子公司通过国家企业信用信息公示系统向社会公示逾期尚未支付中小企业款项信息的，应当披露逾期未支付中小企业款项的金额、对中小企业供应商的账期设置、逾期账款的形成原因、是否涉及诉讼仲裁等情况，并披露解决方案。 | J16: 基础指标（一）基本要求。依法依规开展生产经营活动，不存在严重违法违规行为，未列入“严重失信主体名单”，维护行业自律。正常生产，未列入“经营异常名录”。依法依规缴纳税款及社会保险费，按规定支付职工薪酬。不存在从事《中华人民共和国 反垄断法》规定的垄断行为。规范企业公告前，不存在国家有关专项督察通报问题未整改完成事项。 | K16: 工信部《钢铁行业规范条件（2025 年版）》基本要求：依法依规开展生产经营活动，不存在严重违法违规行为，未列入“严重失信主体名单”，维护行业自律。正常生产，未列入“经营异常名录”。依法依规缴纳税款及社会保险费，按规定支付职工薪酬。不存在从事《中华人民共和国反垄断法》规定的垄断行为。规范企业公告前，不存在国家有关专项督察通报问题未整改完成事项。 | T16: 来源：各地高级人民法院被执行人查询系统 | U16: 来源：各地高级人民法院被执行人查询系统 | V16: 失信事件（如法院被执行人等）能够从合同履约和信用管理角度反映企业的诚信经营状况，在转型融资过程中对金融机构的授信决策具有参考价值。但其与低碳转型绩效的直接关联较弱，建议作为可选负向指标纳入体系，作为企业整体合规风险评估的辅助依据。
A17: 转型表现 | B17: 财务表现 | C17: 吨产品净收入 | D17: 按利润表、季度或年度报告等口径中披露的钢铁产量（吨）、归属于上市公司股东的扣除非经常性损益的净利润（元）等业务和财务数据，考虑自身历史和行业水平分析吨钢净利润变化情况 | G17: 第十三条（一） 气候相关风险和机遇对企业报告期间的财务状况、经营成果和现金流量的影响。 | H17: 金融机构根据转型方案，综合考虑企业经营情况、降碳力度等因素，提供建设和运营融资支持 | O17: 转型收入：3.5 绿色和脱碳的年收入增长；3.6 绿色和脱碳年收入（占总收入的百分比）。按照企业是否有目标和数据及其器详细程度，并根据减少提数据梯度，分6个评分阈值进行评价； 钢铁行业调整系数说明——转型领导者：通过绿色活动或产品（至少部分）收入证明转型进展；展示转型的实质性进展，其中绿色活动或产品贡献了显着的收入份额。 | T17: 来源：24年可持续发展报告、24年年度报告 可持续发展报告：附录 1 主要数据指标-净利润 公司年报：产销量情况分析表-生产量合计 | U17: 来源：24年年度报告 钢产品生产量；主营业务收入-成本=净利润 | V17: 前期设置"吨产品净收入"指标，初衷是从单位产品收益视角观察企业在转型过程中的盈利能力变化。但进一步分析后发现，该指标主要反映企业整体财务表现及产品定价能力，受市场价格波动等外部因素影响较大，与低碳转型绩效之间缺乏直接因果关系，无法有效衡量企业转型的实际进展。因此建议删除该指标，以增强指标与转型主题的相关性。
C18: 高附加值产品竞争力 | D18: 采用季度或年度报告等口径中披露的钢铁业务收入、钢铁销售量等业务、财务数据，通过吨钢销售均价（元/吨）得到企业的销售均价相对于行业均价的差距，反应市场对该企业高附加值产品的溢价支付意愿。 | F18: 9、产品结构优化 9.1 开发高强高韧、耐蚀耐磨、轻量化、长寿命的钢铁绿色设计产品 | H18: 一（一）3.投资活动要在《河北省钢铁行业转型金融支持经济活动目录（2025年版）》范围内（目录中包含开发高强高韧、耐蚀耐磨、轻量化、长寿命的钢铁绿色设计产品） | K18: 《钢铁行业稳增长工作方案（2025—2026年）》：增强高端产品供给能力。聚焦高端装备、核心基础零部件等领域所需高性能轴承钢、齿轮钢、高温合金、工模具钢等关键钢材，组织钢铁企业联合上下游企业、高校、科研院所等开展产业链协同攻关。持续发挥船舶与海工、超超临界等新材料重点平台作用，加快产品应用验证和迭代升级。 2022年9月，工信部等四部门联合印发的《原材料工业“三品”实施方案》明确提出，到2025年要实现“高温合金、高性能特种合金、半导体材料、高性能纤维及复合材料等产品和服务，对重点领域支撑能力显著增强”的目标。该方案特别将“高性能特种钢”列为需要支持鼓励研发和产业化的关键基础材料，表明超高强钢已成为国家战略的重要组成部分。 《标准提升引领原材料工业优化升级行动方案（2025—2027年）》进一步将“特种装备用钢”、“高性能特种钢”等先进基础材料标准修订列为重点。 | T18: 来源：24年可持续发展报告、24年年度都报告 环披报告：附录 1 主要数据指标-营业总收入、 年度报告：产销量情况分析表-钢材销售量、24年度报告-合并资产负债表- EBITDA（税息折旧及摊销前利润）-营业利润+固定资产折旧+使用权资产折旧 + 无形资产摊销+长期待摊费用摊销 | U18: 来源：24年年度报告 钢产品销售量；主营业务收入 | V18: 前期设置"高附加值产品竞争力"指标，初衷是通过产品价格溢价衡量企业产品结构升级与技术含量提升情况。但进一步审视后发现，产品溢价主要反映市场对该企业产品的支付意愿，受供需关系影响较大，与企业低碳转型绩效并无直接关联。同时，该指标拟体现的产品结构升级内容已通过"产品结构优化"指标得到覆盖。因此建议删除该指标，避免重复计量，增强体系聚焦性。
C19: 绿色低碳转型债券 | D19: 公司在近五年内为绿色低碳转型相关债券发行人，且披露相关债券运用情况 | K19: 《关于进一步优化绿色及转型债券相关机制的通知》拓宽转型债券发行人范围，拓展转型债券募集资金用途，指出转型债券将支持有转型需求的企业，不限于钢铁、有色、石化等传统八大行业，进一步拓展转型债券发行人主体范围，对于募集资金用途，通知指出企业可按有关部委或相关主管部门制定的转型目录等标准发行转型债券，用于与碳达峰碳中和目标相适应、具有减污降碳和能效提升作用的项目及其他相关经济活动，将有助于推动传统行业转型升级，促进转型债券市场进一步扩容。 | L19: 确定资本分配一致性，明确表明资本支出与到2050年实现净零排放是一致的。在构建投资组合时，考虑能够推动实体经济脱碳的不同的资产类别和投资；使用系统方法识别资产类别变体，以增加气候解决方案的风险敞口并降低碳强度；将净零目标与标准指标一起纳入投资组合建设。理想情况下，额外的调整目标应涵盖脱碳和气候解决方案。 | M19: CTB要求将募集资金用于合格气候转型项目，而气候转型项目的定义包含以下范畴：资产、投资与经营活动，高排放资产的提前淘汰与拆除，以及与高排放活动相关的研发支出等——这些活动须能够实现显著且可量化的温室气体规避、减排或清除。 | N19: 企业承诺将所有未来资本支出与其长期温室气体目标或《巴黎协定》将全球气温增幅限制在1.5摄氏度的目标保持一致。企业同时必须披露将未来资本支出与其减碳目标相一致的方法。 | T19: 来源：2024年度报告-第九节 债券相关情况 披露了低碳转型绿色债券募集资金所投向的绿色项目进展情况、募集资金所投向的绿色项目环境效益，所遴选的绿色项目环境效益测算的标准、方法、依据和重要前提条件、募集资金所投向的绿色项目预期与/或实际环境效益情况（具体环境效益情况原则上应当根据《绿色债券存续期信息披露指南》相关要求进行披露，对于无法披露的环境效益指标应当进行说明、评估认证机构相关情况 | U19: 无 | V19: 绿色或低碳转型债券的发行本身并不直接等同于转型成效，单纯以发行次数或规模进行量化评价，可能误判企业真实转型水平。该指标如果被认为有必要纳入评价体系，可能更适合拆解为“是否参与”“资金用途清晰度”“项目实施与效果披露”“第三方评估”等要素，通过分项赋分方式反映企业在转型金融工具运用方面的规范性与成熟度。例如： （一）是否作为绿色 / 低碳转型债券发行人，是-2分；否-0分 （二）募集资金用途与转型相关性，用途表述笼统（如“用于绿色项目”）-1 分；明确对应具体转型项目/技术路径-2 分；披露项目进展-3分；披露测量的减排效果-4分 （三）是否有第三方评估/认证，是-2分；否-0分
B20: 碳排放表现 | C20: 碳价敏感度 | D20: 采用季度或年度报告等口径中披露的EBITDA（税息折旧及摊销前利润）、市场碳价等业务、财务数据，形成理论碳成本占企业经营利润的比例，衡量企业盈利对碳价（尤其是潜在或未来碳价格）的敏感程度。 | G20: 第三十八条 对于内部碳定价，企业应当说明在决策中是否以及如何应用碳价格（如投资决策、转移定价以及情景分析），披露其内部用于评估温室气体排放成本的每吨温室气体排放的价格。企业可以使用影子价格、内部税费等内部碳定价方法。 | K20: 《全国碳排放权交易市场覆盖钢铁、水泥、铝冶炼行业工作方案》：四、实施配额管理 （一）制定年度配额总量和分配方案。生态环境部会同国务院有关部门根据国家温室气体排放控制目标，制定钢铁、水泥、铝冶炼行业年度碳排放配额总量和分配方案。在启动实施阶段，2024 年度配额分配量与其经核查的实际碳排放量相等，2025 年度和 2026 年度配额基于碳排放强度控制思路进行分配。在深化完善阶段，对标行业先进水平优化配额分配方法，推动单位产品产量（产出）碳排放不断下降。 | T20: 来源：24年可持续发展报告、2024年年度报表 可持续发展报告：附录 宝钢股份总温室气体排放总量表：温室气体排放总量(类别1+类别2)11024万吨二氧化碳当量 年度报告：合并利润表-EBITDA = 营业利润 + 固定资产折旧 + 使用权资产折旧 + 无形资产摊销 + 长期待摊费用摊销 | U20: 来源：24年可持续发展报告-附录：ESG指标数据（当年数据和基准年数据） 温室气体排放量 年度报告：EBITDA = 营业利润 + 固定资产折旧 + 使用权资产折旧 + 无形资产摊销 + 长期待摊费用摊销 | V20: 碳价敏感度通过企业理论碳成本占经营利润的比例，衡量企业盈利对潜在碳价格变化的敏感程度，有助于识别企业面临的碳价风险敞口及低碳转型的财务必要性。该指标所需数据可从财务报告和企业碳排放披露中提取，在国际转型评估框架中具有一定参考基础，建议作为碳排放表现维度的定量指标纳入评价体系。
C21: 碳排放披露情况 | D21: 1. 核心词：范围1、直接排放、范围2、能源间接排放、范围3、价值链排放 2. 范围3类别词：类别1、采购商品、上下游运输、差旅、员工通勤、废弃物 | E21: 1.转型主体应当对照国家碳达峰碳中和目标，制定并披露科学合理的碳减排目标，主要内容和要求包括：(3）温室气体排放核算范围至少包括范围一和范围二的温室气体排放；条件成熟时，酌情将范围三的温室气体排放纳入核算范围。 | G21: 第二十七条（一）温室气体排放。 第二十八条 企业应当按照范围一、范围二和范围三温室气体排放，分类披露报告期内产生的温室气体绝对排放总量（以吨二氧化碳当量表示）。 | H21: 二（一）企业碳排放相关数据以温室气体排放核查报告为准。 三（二）2.鼓励企业在披露碳排放范围1、范围2数据的基础上，开展范围3的信息披露。 | I21: 第二十四条 披露主体应当核算并披露报告期内的温室气体排放总量，并将不同温室气体排放量换算成二氧化碳当量公吨数。披露主体应当披露温室气体范围1排放量、范围2排放量，鼓励有条件的披露主体披露温室气体范围3排放量。 | K21: 《全国碳排放权交易市场覆盖钢铁、水泥、铝冶炼行业工作方案》：钢铁行业需披露二氧化碳温室气体排放数据，覆盖化石燃料燃烧、工业过程等产生的温室气体直接排放，不覆盖因消耗电力、热力等带来的间接排放。 | L21: 1. 披露基线投资组合范围1和2融资排放量，投资组合范围3排放量单独披露，主权相关资产单独披露； 5披露：披露运营范围1、2，以及重大范围3的排放； | N21: 企业报告了范围1和范围2，或范围1、范围2和范围3的温室气体排放信息。如果企业仅披露范围1温室气体排放，应被评为“否”。 企业单独披露范围3排放，全部或一个或多个类别，或者提供范围1、范围2和范围3温室气体排放量总额。 在一些部门，范围3排放的特定类别具有重大意义，在生命周期排放中占很大份额。在这些行业，要求企业具体披露相关类别的排放量： （1）对于汽车制造、煤矿开采、石油天然气生产和石油天然气分销公司，要求披露使用销售产品产生的范围3排放； （2）对于食品生产商，要求披露采购商品和服务的范围3排放； （3）对于多元化的矿工，要求披露销售产品加工过程中的范围3排放； 对于化学品公司，要求披露采购商品和服务以及销售产品使用的范围3排放。 | R21: 1 主体应当披露其全球范围内的范围 1 温室气体（GHG）总排放量，以《京都议定书》涵盖的七种温室气体的二氧化碳当量（CO₂-e）公吨为单位， 2. 范围 1 排放的定义与计算方法 范围 1 排放的定义和计算，必须遵循《温室气体核算体系：企业核算与报告标准》（GHG Protocol）（修订版，2004 年 3 月）中所载的方法，该标准由世界资源研究所（WRI）与世界可持续发展工商理事会（WBCSD）共同发布。 3 受限排法规约束的排放占比主体应当披露其全球范围 1 温室气体总排放量中，受相关司法管辖区限排法律、法规或计划约束的排放占比。这些法规旨在直接限制或减少温室气体排放，例如：总量控制与交易机制碳税或收费 / 免税制度 其他排放控制措施（如命令控制型措施）许可机制 4 主体应当讨论自上一报告期以来的排放变化，包括该变化是否是由于减排、撤资、收购、合并、产出变化或计算方法变化造成的。 5 与其他披露的协调：如果主体向 CDP 或其他实体（如国家监管披露计划）报告的温室气体排放，在范围或合并方法上与本指引存在差异，主体可披露这些数据，但主要披露仍需遵循本指引。 6 主体可以选择以下方法进行排放披露，只要数据来源可靠：连续排放监测系统（CEMS）、工程计算、物料平衡计算。 | T21: 来源：24年可持续发展报告 附录 宝山钢铁股份有限公司钢铁板块：购买货物和服务的运输、员工通勤、产品运输、废物处置、采购货物和服务的排放（制造相关）等 | U21: 来源：24年可持续发展报告-附录：ESG指标数据（当年数据和基准年数据） 温室气体排放总量 | V21: 碳排放披露是开展后续定量评价的基础性前提，体现企业信息透明度与管理成熟度，建议作为基础指标保留。
C22: 物理碳排放强度 | D22: 单位粗钢产量所产生的范围一和范围二的碳排放量 | E22: 1.转型主体应当对照国家碳达峰碳中和目标，制定并披露科学合理的碳减排目标，主要内容和要求包括：(2）短、中、长期的碳减排目标，以定量的碳排放总量或者单位产品碳排放强度表示。 2.转型主体应当制定并披露技术可行的转型计划，主要内容和要求包括：(3）测算每个阶段转型工作的碳减排效果，说明碳减排效果的累积能够实现短、中、长期碳减排目标。 | G22: 第二十七条（一）温室气体排放。 第四十条 企业应当披露与特定业务模式、活动或者表明企业所处行业的其他共同特征相关的行业特定指标。 | H22: 一（一）2.短期目标要以定量的碳排放强度表示，中、长期目标要兼顾碳排放总量 一（一）3.二是投资计划涉及的主要工序碳排放预期值要低于河北省钢铁行业碳排放基准值。 | K22: 《全国碳排放权交易市场覆盖钢铁、水泥、铝冶炼行业工作方案》：四、实施配额管理 （一）制定年度配额总量和分配方案中明确提出“2025 年度和 2026 年度配额基于碳排放强度控制思路进行分配。在深化完善阶段，对标行业先进水平优化配额分配方法，推动单位产品产量（产出）碳排放不断下降。” 2025 年最新发布的《绿色工厂评价通则》（GB/T 36132-2025）；单位产值（或单位产品）的二氧化碳当量（CO₂e）排放量需明确年度减排目标，且近 3 年平均降幅≥3%；需覆盖范围 1（直接排放，如燃烧） 和范围 2（外购能源间接排放），重点行业（如化工、火电）需额外核算范围 3（供应链间接排放）。 | L22: 1、排放强度符合部门和地区2050年路径，并且其运营模式将保持这一表现的资产； 2. 排放表现：当前的绝对值或排放强度至少等于相关净零路径； | M22: CTB：3.1 关键绩效指标的选择 对于高排放的可持续发展挂钩债券（SLBs）发行人，一个或多个关键绩效指标（“KPIs”）应监测温室气体（GHG）减排——可以是直接结果（即绝对/强度温室气体排放指标）或辅助指标（即推动温室气体减排目标的杠杆指标） | O22: 减排量（长期）： （1）有针对性的减少绝对1、2级排放强度：按照企业是否有目标与数据及其详细程度、减排数据梯度（有无-35%），分6个评分阈值（0-5）进行评价； （2）实现的减少绝对范围3排放:按照企业是否有目标与数据及其详细程度、减排数据梯度（有无-35%），分6个评分阈值（0-5）进行评价； （3）实现的减少排放强度（范围1、2排放）:按照企业是否有目标与数据及其详细程度、减排数据梯度（有无-35%），分6个评分阈值（0-5）进行评价； 减排量（短期）： （1）有针对性的减少绝对1、2级排放强度：按照企业是否有目标与数据及其详细程度、减排数据梯度（有无-35%），分6个评分阈值（0-5）进行评价； （2）实现的减少绝对范围3排放:按照企业是否有目标与数据及其详细程度、减排数据梯度（有无-35%），分6个评分阈值（0-5）进行评价； （3）实现的减少排放强度（范围1、2排放）:按照企业是否有目标与数据及其详细程度、减排数据梯度（有无-35%），分6个评分阈值（0-5）进行评价； | P22: （5）温室气体减排：减少、清除和抵消排放量对于实现温室气体减排目标的相对贡献。 | R22: 1 主体应当披露其全球范围内的范围 1 温室气体（GHG）总排放量，以《京都议定书》涵盖的七种温室气体的二氧化碳当量（CO₂-e）公吨为单位， | T22: 来源：24年可持续发展报告、24年年度报告（当年与基准年数据） 环披报告：附录 宝钢股份总温室气体排放总量表：温室气体排放总量(类别1+类别2)11024万吨二氧化碳当量 公司年报：产销量情况分析表-生产量合计 | U22: 来源：24年可持续发展报告-附录：ESG指标数据（当年数据和基准年数据） 温室气体排放总量 24年年度报告-钢产品产量 | V22: 两类碳强度指标分别从产量与经济产出角度反映企业排放效率，营收碳排放强度从经济产出角度衡量单位营业收入的碳排放量，能够反映企业在创造经济价值的同时实现减排的效率，与物理碳排放强度形成互补，共同构成碳排放表现的量化评价维度。建议保留该指标，采用与物理碳排放强度相同的分档评价逻辑，结合绝对水平和年际变化综合评分。
C23: 营收碳排放强度 | D23: 单位营业收入所产生的范围一和范围二的碳排放量 | E23: 1.转型主体应当对照国家碳达峰碳中和目标，制定并披露科学合理的碳减排目标，主要内容和要求包括：(2）短、中、长期的碳减排目标，以定量的碳排放总量或者单位产品碳排放强度表示。 2.转型主体应当制定并披露技术可行的转型计划，主要内容和要求包括：(3）测算每个阶段转型工作的碳减排效果，说明碳减排效果的累积能够实现短、中、长期碳减排目标。 | G23: 第二十七条（一）温室气体排放。 第四十条 企业应当披露与特定业务模式、活动或者表明企业所处行业的其他共同特征相关的行业特定指标。 | M23: CTB：3.1 关键绩效指标的选择 对于高排放的可持续发展挂钩债券（SLBs）发行人，一个或多个关键绩效指标（“KPIs”）应监测温室气体（GHG）减排——可以是直接结果（即绝对/强度温室气体排放指标）或辅助指标（即推动温室气体减排目标的杠杆指标） | T23: 来源：24年可持续发展报告（当年与基准年数据） 附录 1 主要数据指标：营业总收入3,221.16亿元；附录 宝钢股份总温室气体排放总量表：温室气体排放总量(类别1+类别2)11024万吨二氧化碳当量 | U23: 来源：24年可持续发展报告-附录：ESG指标数据（当年数据和基准年数据） 温室气体排放总量下面的“温室气体排放强度”单位是吨二氧化碳当量/每百万元营收
C24: 碳排放效率 | D24: 碳减排效率用于衡量企业在实现营业收入增长的同时，其碳排放减少与经济增长之间的协同程度，反映企业“低碳增长”的质量。 | G24: 第四十四条 企业应当披露其每项气候目标实现情况的绩效信息，以及对企业绩效趋势或者变化的分析 | I24: 第二十七条 披露主体应当披露温室气体减排实践的相关信息，包括参与各项减排机制的情况、减排目标、减排措施（如管理措施、资金投入、技术开发等）及其成效等。 | T24: 来源：24年可持续发展报告（近两年数据） 附录 1 主要数据指标：营业总收入3,221.16亿元；附录 宝钢股份总温室气体排放总量表：温室气体排放总量(类别1+类别2)11024万吨二氧化碳当量 | U24: 来源：24年可持续发展报告、24年年度报告（当年数据和基准年数据） 可持续报告：附录：ESG指标数据：温室气体排放总量（范围 1+ 范围 2） 2024年 35,612,055.11吨二氧化碳当量； 年度报告：营业收入1092.03亿元 | V24: 前期设置"碳排放效率"指标，主要是希望从碳排放与经济产出的协调性角度，衡量企业低碳增长的质量。但进一步分析后发现，该指标与"物理碳排放强度"和"营收碳排放强度"在概念上高度重叠，独立设置将导致指标体系内部冗余。建议将相关内涵通过已有强度指标的分档设计加以体现，删除单独的碳排放效率指标，以提升体系的精简度。
C25: 自身减排速度 | D25: 企业当年的“同比减排幅度”，相对于行业当年的“平均同比减排幅度”，处在什么位置。 | G25: 第四十四条 企业应当披露其每项气候目标实现情况的绩效信息，以及对企业绩效趋势或者变化的分析 | H25: 一（一）3.二是投资计划涉及的主要工序碳排放预期值要低于河北省钢铁行业碳排放基准值。 | I25: 第二十七条 披露主体应当披露温室气体减排实践的相关信息，包括参与各项减排机制的情况、减排目标、减排措施（如管理措施、资金投入、技术开发等）及其成效等。 | O25: 钢铁行业调整系数说明——钢：1. 若当前排放强度显著高于行业平均水平（+30%），则采用否定性修饰语。2. 若当前排放强度已显著低于行业平均水平（-30%），则采用正向修正系数。 | R25: 4 主体应当讨论自上一报告期以来的排放变化，包括该变化是否是由于减排、撤资、收购、合并、产出变化或计算方法变化造成的。 | T25: 来源：24年可持续发展报告、24年年度报告（近两年数据） 环披报告：附录 宝钢股份总温室气体排放总量表：温室气体排放总量(类别1+类别2)11024万吨二氧化碳当量 公司年报：产销量情况分析表-生产量合计 | U25: 来源：24年可持续发展报告、24年年度报告（当年数据和基准年数据） 可持续报告：附录：ESG指标数据：温室气体排放总量（范围 1+ 范围 2） 2024年 35,612,055.11吨二氧化碳当量； 年度报告：钢产品生产量 2,016.22 万吨 | V25: 前期设置"自身减排速度"指标，主要是希望从动态视角衡量企业减排行动的相对速度，考察企业减排进展与行业均值的对比关系。但进一步分析后发现，该指标计算需要逐年对标行业均值，数据处理复杂度较高，且横向可比性受行业样本选取与更新的影响，实操难度较大。此外，其所反映的内容已部分包含于碳排放强度等核心指标的年际变化分析中。建议暂不纳入，视数据积累情况在后续版本中酌情引入。
B26: 能源使用 | C26: 可再生能源占比 | D26: 自发可再生能源电量，是指企业在自身生产经营边界内，通过自建或控股的可再生能源发电设施，所产生并被企业自身消费的电力。 能源消耗总量：企业当期披露的能源消耗总量（单位 MWh） | F26: 2. 清洁能源替代: 2.1 分布式光伏发电技术; 2.2 储热调峰; 2.3可再生能源制氢气和氧气用于钢铁冶炼 | G26: 第十二条（二）当前和计划采取的用于减缓和适应气候变化的直接措施（如节能产品认证、碳标识认证，改变生产工艺或者设备、搬迁设施、调整劳动力结构以及改变产品规格等）； | H26: 一（一）3.投资活动要在《河北省钢铁行业转型金融支持经济活动目录（2025年版）》范围内（目录中包含分布式光伏发电技术、风力发电设施建设和运营） | I26: 第三十五条（二）清洁能源使用情况，包括但不限于风能、太阳能、水能、地热能、生物质资源、海洋能、天然气等清洁能源的种类、总量、比例等； | M26: CTB：项目类别的初步且非详尽清单包括但不限于： 4. 低碳燃料，包括其生产、使用、采购及相关基础设施投资。 | R26: (3) 消耗的可再生电力百分比：企业应披露其消耗的来自可再生能源的电力数量（以 GJ 为单位），分为自发电和直接合同。其消耗的可再生能源百分比。 | T26: 来源：24年可持续发展报告（当年与基准年数据） 附录 1 主要数据指标：可再生能源-自发可再生能源电量：2024合计 377,164兆瓦时 附录 1 主要数据指标：能源消耗-能源总量：2024年合计267,429,687兆瓦时 | U26: 来源：2024年可持续发展报告（当年数据和基准年数据） 附录：ESG指标数据：自发绿电（屋顶光伏、风电）2024年 105,387兆瓦时；能源消耗总量 2024年 86,280,115兆瓦时 | V26: 可再生能源占比反映企业能源结构的清洁化程度，是国内外政策框架普遍关注的能源转型核心指标。上市钢铁企业在可持续发展报告中对可再生能源相关数据通常具有较好的披露基础，且指标计算方法标准化程度较高，具备较好的横向可比性，建议作为能源结构表现维度的核心指标予以保留。
D27: 外购绿电包括： 绿电交易电量 绿证对应电量（如披露） 能源消耗总量：企业当期披露的能源消耗总量（单位 MWh） | G27: 第四十五条 企业计划使用外购减排量作为补充手段抵销其温室气体排放量，以实现温室气体净排放量目标的，应当在说明其计划使用的减排量时披露下列信息：（一）实现温室气体净排放量目标依赖外购减排量使用的程度和方式；（二）对减排量进行认证的独立第三方名称及认证体系；（三）减排量所属的自愿减排交易机制名称，产生减排量的项目所处国别；（四）减排量的类型，包括抵销所用减排量源自何种自愿减排项目；（五）为使可持续信息基本使用者了解企业计划使用的减排量的可信度和完整性所需的其他因素（如项目业主对所提供材料真实性、完整性和有效性负责的承诺书）。 | K27: 《关于2025年可再生能源电力消纳责任权重及有关事项的通知》明确在电解铝行业基础上，2025年增设钢铁、水泥、多晶硅行业和国家枢纽节点新建数据中心绿色电力消费比例。《通知》要求，2025年，钢铁、水泥、多晶硅行业要求绿电消费比例为25.2%～70%之间， | R27: 企业应披露（3）其消耗的来自可再生能源的电力数量（以 GJ 为单位），分为（3a）自发电和（3b）直接合同。其消耗的可再生能源百分比。 可再生能源的范围包括实体消耗的可再生燃料、实体直接生产的可再生能源和实体购买的可再生能源，如果通过明确包含可再生能源证书 (REC) 或原产地保证 (GO)、Green-e Energy 认证的公用事业或供应商计划或明确包含 REC 或 GO 的其他绿色电力产品购买，或 Green-e Energy 认证的 REC 与电网电力配对。 | T27: 来源：24年可持续发展报告（当年与基准年数据） 附录 1 主要数据指标：可再生能源-外购可再生能源电量：2024合计1,916,874兆瓦时，外购可再生能源绿证电量：2024合计2,660,300兆瓦时 附录 1 主要数据指标：能源消耗-能源总量：2024年合计267,429,687兆瓦时 | U27: 来源：2024年可持续发展报告（当年数据和基准年数据） 附录：ESG指标数据：外购绿电 2024年302,054兆瓦时，能源消耗总量 2024年 86,280,115兆瓦时 | V27: 外购绿电在一定程度上可降低企业范围二排放，但其转型含义具有明显的阶段性和外部依赖性： 受制于区域绿电供给、市场机制和政策补贴安排； 不一定伴随企业自身生产系统或能源结构的实质性改变。 因此，可将外购绿电作为可选指标，用于补充刻画企业在现阶段条件下的减排努力，但不作为转型绩效的刚性判断依据。
C28: 能耗强度or能耗达标？ | D28: 能耗强度指标吨钢综合能耗，而能耗达标就是看单位产品能源消耗量是否满足国家及地方政府相关规定要求。 | F28: 1. 系统能效提升; 1.1 上升管余热回收 1.2 烧结漏风率综合治理 1.3 水封式烧结环冷机 1.4 烧结返矿冷压球团矿 1.5 球团固固换热显热回收 1.6 高炉大比例球团冶炼 1.7 高炉炉顶均压煤气回收 1.8 转炉一次干法净化回收 1.9 转炉中低温余热回收 1.10 电炉烟气显热回收 1.11 高效煤气发电 1.12 低温余热有机工质朗肯循环（ORC）发电 1.13 电机、变压器、水泵、风机等公辅设施能效提升 | K28: 通过环评审批的新建和在建钢铁企业高炉、转炉或电弧炉冶炼工序的单位产品能耗应达到《工业重点领域能效标杆水平和基准水平（2023年版）》中的高耗能行业能效标杆水平：高炉工序能效标杆水平为 361 千克标准煤/吨（对原料中钒钛磁铁矿用量每增加 10%，高炉工序能耗增加 3 千克标准煤/吨）；转炉工序能效标杆水平为-30 千克标准煤/吨；电弧炉冶炼（30 吨＜公称容量＜50 吨）能效标杆水平为 67 千克标准煤/吨；电弧炉冶炼（公称容量≥50 吨）能效标杆水平为 61 千克标准煤/吨（注：电弧炉冶炼全不锈钢单位产品能耗提高 10%）。现有钢铁企业高炉、转炉或电弧炉冶炼工序的单位产品能耗达到能效基准水平以上，基准水平分别为435千克标准煤/吨、-10千克标准煤/吨、86千克标准煤/吨、72千克标准煤/吨。 铸造用生铁企业单位产品能耗应达到地方标准。如《铸铁生产主要工序单位产品能源消耗限额》（DB13/T 2129-2014 ）中单位产品能耗限定值烧结工序≤59 千克标准煤/吨，球团工序≤35 千克标准煤/吨，高炉工序≤435 千克标准煤/吨。 《钢铁行业节能降碳专项行动计划》，至2030年底，钢铁行业主要工序能效进一步提升，主要用能设备能效基本达到先进水平，吨钢综合能耗和碳排放明显降低，用能结构持续优化 | R28: 能源管理主题下，企业应披露（1）其消耗的能源总量，以千兆焦耳（GJ）为单位。 | T28: 来源：2024年可持续发展报告 吨钢综合能耗达4.5兆瓦时/吨粗钢 | U28: 来源：2024年可持续发展报告 吨钢综合能耗535.47千克标准煤/吨粗钢 | V28: 能耗强度与碳排放强度存在较高同质性；而能耗达标指标在政策上依据具体工序设定限额，但企业披露通常不按工序拆分，导致数据可得性较差。综合考虑指标区分度与可操作性，建议不单独设置该指标。
B29: 水资源利用 | C29: 用水效率 | D29: 单位粗钢水消耗量，指企业在生产过程中对水资源的消耗情况 用水效率 = 当期总用水量 ÷ 当期粗钢产量 | E29: 无重大损害原则。即转型金融支持的经济活动或企业应当对污染防控、资源节约和生态保护等其他环境目标无重大损害。 | G29: 第四十条 企业应当披露与特定业务模式、活动或者表明企业所处行业的其他共同特征相关的行业特定指标。 | H29: 一（一）3.投资活动要在《河北省钢铁行业转型金融支持经济活动目录（2025年版）》范围内（目录中包含钢铁生产不同工序水质分质供水技术、废水深度处理回用组合工艺、废水零排放处理和回用技术、循环水水质动态监测与水处理优化技术，适用于节水节能、钢铁行业废水处理回用等场景） | I29: 第三十六条 （一）水资源使用的基本情况，包括但不限于总耗水量（以吨计算）及使用强度（如以每产量单位计算）等； （二）水资源节约目标以及具体措施，水资源回收利用情况及水资源使用存在的具体困难（如有）。 | J29: 基础指标（四）资源消耗。资源综合利用符合国家有关规定。水资源消耗符合国家有关强制标准规定，不存在未经批准擅自取用地下水行为。 | K29: 《工业用水定额：钢铁》按照主要生产工序进一步细分制定，分别制定了烧结、球团、焦化、炼铁、炼钢、轧钢等工序用水定额。 | R29: （1）按来源划分的总取水量 （2）总用水量； （3）从缺水地区取水和消耗的水量百分比，以及基线水压力高或极高地区的用水量百分比 1 实体应披露从所有来源取水的数量，以兆升、千立方米为单位，按来源分类。 2 如果很大一部分取水来自非淡水源，则实体可按来源披露其供应部分。 3 该实体应披露其直接运营中消耗的水量，以兆升、千立方米为单位。 4 企业应披露在基线水资源压力高或极高地区，从水资源紧张地区消耗的水量占总消耗水量的百分比。 5 如果此披露的信息是估算或模拟的，而不是来自直接测量，则企业应解释其估算方法。 | T29: 来源：24年可持续发展报告、24年年度报告（当年数据和基准年数据） 环披报告：附录 1 主要数据指标：水资源-年度总用水量：135.67百万立方米 年度报告：产销量情况分析表-生产量合计 | U29: 来源：24年可持续发展报告、24年年度报告（当年数据和基准年数据） 可持续报告：附录 ESG指标数据：水资源管理-总耗水量 50,146,778立方米 年度报告：钢产品生产量 2,016.22 万吨 | V29: 用水效率以单位粗钢产量水消耗量衡量企业对水资源的利用效率，是多个转型金融和企业可持续披露框架中明确要求的环境绩效指标。上市钢铁企业通常在可持续发展报告中具备相关数据披露，且具有一定的行业可比基础，建议作为水资源表现维度的核心指标予以保留。
C30: 水资源回收利用率 | D30: 企业在生产过程中回用的水量占总用水量的比率，衡量企业是否通过技术手段有效回收和再利用水资源，减少对外部水资源的依赖 | E30: 无重大损害原则。即转型金融支持的经济活动或企业应当对污染防控、资源节约和生态保护等其他环境目标无重大损害。 | G30: 第四十条 企业应当披露与特定业务模式、活动或者表明企业所处行业的其他共同特征相关的行业特定指标。 | H30: 一（一）3.投资活动要在《河北省钢铁行业转型金融支持经济活动目录（2025年版）》范围内（目录中包含废水深度处理回用组合工艺、废水零排放处理和回用技术、循环水水质动态监测与水处理优化技术，适用于节水节能、钢铁行业废水处理回用等场景） | I30: 第三十六条 （一）水资源使用的基本情况，包括但不限于总耗水量（以吨计算）及使用强度（如以每产量单位计算）等； （二）水资源节约目标以及具体措施，水资源回收利用情况及水资源使用存在的具体困难（如有）。 | K30: 《工业废水循环利用实施方案》（工信部联节〔2021〕213号）明确提出到2025年，钢铁行业规模以上工业用水重复利用率要达到97%以上，推动钢铁企业加强节水管理和技术改造，推广应用高效循环用水处理、高浓度有机废水回用等先进工艺技术。 | T30: 没有披露 | U30: 来源：24年可持续发展报告-附录：ESG指标数据 2024年水循环利用比例为98% | V30: 前期设置"水资源回收利用率"指标，主要是希望从循环利用角度补充衡量企业的水资源管理水平。但在实际数据收集过程中发现，该指标企业间披露口径不统一，可比性受限，且所反映的水资源管理内容与"用水效率"指标存在较大重叠。综合考虑数据可得性与体系简洁性，建议暂不独立保留，可在"用水效率"评价框架中将水资源回收利用情况作为加分项加以考量。
B31: 生态保护 | C31: 生物多样性 | D31: 企业在生物多样性保护方面表现，比如制度或组织架构建设、具体措施和实际成效，包括保护区域的生态恢复、物种多样性保护及生态环境修复等。 | E31: 无重大损害原则。即转型金融支持的经济活动或企业应当对污染防控、资源节约和生态保护等其他环境目标无重大损害。 | G31: 第四条 企业还应当披露本准则第二章至第五章未涵盖的重要的气候相关影响信息。 | H31: 一（一）2.技术路径应遵循无重大损害原则 | I31: 第三十二条 披露主体生产经营活动对生态系统和生物多样性产生重大影响的， | S31: 2) 技能与文化：为设计、实施与监督转型计划的团队和个人提供培训与发展支持，使其具备足够的技能与知识以履行职责（包括董事会及高级管理层层面）。实施变革管理计划，促进开放沟通，并将净零转型计划融入组织的文化与实践中。 ・现有及所需的能力、技能与知识摘要，以及评估方法 ・资源需求与将转型计划要素融入文化与实践的变革管理计划摘要 ・获取气候相关资源的渠道摘要 | T31: 来源：24年可持续发展报告 宝钢股份通过建立贯穿项目规划、建设、运营全过程的生物多样性保护管理体系，系统推进生态保护战略落地。报告期内，我们开展了一系列以生物多样性保护为主题的项目，持续完善工业活动与自然生态的协同发展路径。严格遵守《中华人民共和国环境影响评价法》及其相关法律法规的规定，确保新建项目选址避开自然保护区范围。依据 IUCN 红色名录及国家保护物种名录，对运营点所在区域的生物多样性现状进行综合评估与分析，并据此制定科学的管理与保护规划。对海外采购的原材料进行严格检测，以预防外来物种的入侵风险。严格监控并管理废气、废水及废弃物的排放，以确保不对自然生态环境造成不利影响。与地方监测站携手合作，共同实施物种监测项目，积极推进野生动物保护行动。 | U31: 来源：24年可持续发展报告 根据生物多样性风险评估的结论，公司制定了旨在最小化 业务运营对生物多样性影响的短期及长期管理规划。公司 针对高风险区域，特别制定了生物多样性风险缓解行动方 案，并广泛实施了生态保护和补偿措施，确保运营活动不 对生物多样性构成任何负面影响 在新项目建设与运营全流程中，需参照相关要求进行生物多样性保护和土地利用评估，确保项目开发与运营 地点远离生态保护红线及生态多样性脆弱地区，以保护自然栖息地、湿地、森林、野生动物廊道和农业用地， 尽量降低对周边环境和社区的不利影响 | V31: 生物多样性保护已成为国际可持续披露框架（如TNFD）的重要议题，部分国内可持续发展报告亦开始涉及相关内容。虽然目前钢铁行业企业的披露深度有限，但作为ESG综合绩效的重要组成部分，建议采用定性评价方式，以有无相关制度建设、具体措施和实际成效为评价依据，纳入评价体系以体现企业在生态保护方面的关注程度。
B32: 公正转型 | C32: 公益捐赠 | D32: 公益捐赠可以适当反映企业在转型过程中对社会公共利益与弱势群体的支持能力，是公正转型中“社会缓冲机制”的重要体现评估企业在公益捐赠上表现出的投入力度与行为稳定性，综合判断其社会承诺的财务实质性及长期可信度。 | T32: 来源：24年可持续发展报告 公益捐赠-社会捐赠总额：8121.33万元 | U32: 来源：2024年可持续发展报告-附录：ESG指标数据 对外捐赠金额：75万元 | V32: 公益捐赠在一定程度上可反映企业对社会公共利益的关注，但与转型绩效评价的核心逻辑相关度较低，且受企业经营状况、行业景气周期等外部因素影响较大，难以有效体现公正转型的实质性内涵。更重要的是，目前主要转型评价框架中鲜有将公益捐赠纳入转型评价指标体系的先例。因此建议删除该指标，转而聚焦员工培训和稳就业与促就业等更具转型针对性的公正转型指标。
C33: 员工培训 | D33: 本指标用于评估企业是否关注并投入员工能力建设，尤其是在转型相关技能方面。 考虑到企业披露口径差异较大，本指标采用是否类累加赋分方式，不对不同披露口径进行强制可比性要求。 | E33: 公正转型原则。应当关注转型可能产生的经济社会影响，并采取措施缓解负面影响。 | G33: 第四条 企业还应当披露本准则第二章至第五章未涵盖的重要的气候相关影响信息。 | H33: 一（一）2.三是对转型过程中可能产生的经济社会影响，要遵循公正转型原则，做好评估及应对预案。 | I33: 第五十条（三）员工职业发展与培训的基本情况，包括但不限于公司职位体系设置情况，员工晋升、选拔与职业发展机制，员工培训类型、次数、开展情况，以及年度培训支出金额、员工培训覆盖率等。 | Q33: 5.5 技能、能力与培训 主体应当披露其为实现转型计划的战略愿景，已采取或计划采取的、用于在全公司范围内评估、维持和培养相应技能、能力与知识的行动相关信息。 披露建议 作为此部分的内容，主体应当披露： a. 关于主体如何评估其在全公司范围内是否具备有效设计、制定、交付和治理转型计划所需的技能、能力与知识的信息，以符合其战略愿景 b. 当识别到技能缺口时，说明其已采取或计划采取的、用于获取或培养所需技能的行动 c. 关于其已采取或计划采取的、为董事会及高管层提供有效监督转型计划所需的技能、能力与知识的行动信息 | T33: 来源：24年可持续发展报告（当年数据和基准年数据） 报告期内，宝钢股份共开展环保相关培训 5 场，培训总时长为 34 小时，培训 100% 覆盖宝钢股份四大基地及子公司。 | U33: 来源：2024年可持续发展报告（当年数据和基准年数据） 员工培训总人次 72,029，培训费用 865.13 万元 技术人才培训主要着眼于设备类、安全管理类等专技培训。其 中，后备安全专家培训组织了相关技术人员赴各子公司进行现场 实践，该培训历时 18 天，共计 76 人参与，共完成炼铁、炼钢、 轧钢、焦化四个专业新安全风险辨识管控模版的编制；数智化人 才类共计组织 6 个培训项目，包括人工智能平台、数据库应用高 阶等各类培训，共计 166 人参与。此次培训储备了后备安全专家， 提升了技术人才占比。 面向员工和利益相关方开展生物多样性主题教育和培训，提升生物多样性保护意识和专业性 公司重视提升全体员工对能源高效利用的认识与能力，策划并面向全体员工开展了一系列提升能源使用效率的培训项目，包括日常操作工艺节能减排操作要求、管理层面节能减碳软件应用等。同时，公司邀请行业专家进行授课，通过案例与实操演练，让员工深刻理解节能减排的重要性，并掌握实际应用中的节能技巧。 | V33: 员工培训是公正转型的重要维度，反映企业在转型过程中通过能力建设降低技术变革对员工的负面冲击。钢铁行业在推进工艺升级和技术转型过程中，员工技能培训尤为关键，在多个政策框架中均有明确引导。企业通常具备相关披露基础，建议保留该指标，采用定性分档评价方式，重点考察培训投入规模及与转型技能的相关性。
C34: 稳就业与促就业 | D34: 衡量企业在转型过程中是否避免通过大规模裁员转嫁成本，并通过稳定或扩大就业规模，体现对劳动者和社会的责任承担。 | E34: 公正转型原则。应当关注转型可能产生的经济社会影响，并采取措施缓解负面影响。 | G34: 第四条 企业还应当披露本准则第二章至第五章未涵盖的重要的气候相关影响信息。 | H34: 一（一）2.三是对转型过程中可能产生的经济社会影响，要遵循公正转型原则，做好评估及应对预案。 | I34: 第五十条（一）员工的聘用与待遇等方面的政策及执行情况，包括但不限于报告期内吸纳就业、创造灵活就业岗位的情况，期末在职员工的性别、年龄等构成情况，报告期内支付员工工资和缴纳员工社保、公司劳工纠纷、员工变动、对灵活就业人员的权益保障、招聘录用程序合规与公平透明情况等； | R34: 劳工实践: 1 集体协议涵盖的员工百分比，企业应披露报告日集体协议涵盖的员工总数的百分比。 2 该百分比的计算方法是将集体协议涵盖的员工人数除以雇用的员工总数。 （1）停工次数，实体应披露停工次数、因停工导致的停工总天数（2）总闲置天数 3 该披露不包括因非技术原因导致的停工，例如因待决监管许可而导致的停工，或与社区担忧、社区或利益相关者抵抗或抗议或武装冲突有关的其他延误。 4 实体应提供有关停工的信息，包括相关成本、每次停工的原因（由劳工说明）、对生产的影响、持续停工的状况以及采取的纠正措施。 | T34: 来源：24年可持续发展报告（近三年数据） 附录 1 主要数据指标：雇佣与多元化-员工总数2024年46,048人。 | U34: 来源：24年可持续发展报告（近三年数据） 附录：ESG指标数据-员工基本信息-员工总人数 30,960人 | V34: 稳就业与促就业能够体现企业在转型过程中对劳动者和社会责任的履行程度，是公正转型框架的核心关注点之一。钢铁行业转型可能涉及工艺淘汰和产能调整，就业稳定性评价具有重要的现实意义，且在多个国内政策文件中有明确导向。建议保留该指标，重点评价企业是否避免借转型名义大规模裁员，并通过积极行动稳定和扩大就业。
C35: 劳动纠纷（负向指标） | D35: 衡量因转型调整（如岗位重组、合同解除）引发的、并已进入正式法律或仲裁程序的劳资纠纷数量与严重性。 案由关键字：船员劳务合同纠纷、辞退争议、经济性裁员争议、劳动合同纠纷、劳动争议、劳务合同纠纷、离退休人员返聘合同纠纷、确认劳动关系纠纷、社会保险纠纷、职工破产债权确认纠纷、追索劳动报酬纠纷 | E35: 公正转型原则。应当关注转型可能产生的经济社会影响，并采取措施缓解负面影响。 | G35: 第四条 企业还应当披露本准则第二章至第五章未涵盖的重要的气候相关影响信息。 劳动纠纷可能属于气候相关转型风险（如政策、法律风险）或公正转型影响的体现。 | H35: 一（一）2.三是对转型过程中可能产生的经济社会影响，要遵循公正转型原则，做好评估及应对预案。 | I35: 第五十条（一）员工的聘用与待遇等方面的政策及执行情况，包括但不限于报告期内吸纳就业、创造灵活就业岗位的情况，期末在职员工的性别、年龄等构成情况，报告期内支付员工工资和缴纳员工社保、公司劳工纠纷、员工变动、对灵活就业人员的权益保障、招聘录用程序合规与公平透明情况等； | J35: 基础指标（一）基本要求。依法依规开展生产经营活动，不存在严重违法违规行为，未列入“严重失信主体名单”，维护行业自律。正常生产，未列入“经营异常名录”。依法依规缴纳税款及社会保险费，按规定支付职工薪酬。不存在从事《中华人民共和国 反垄断法》规定的垄断行为。规范企业公告前，不存在国家有关专项督察通报问题未整改完成事项。 | T35: 来源：中国裁判文书网、地方人社局公布的年度劳动争议典型案例/分析报告 | U35: 来源：中国裁判文书网、地方人社局公布的年度劳动争议典型案例/分析报告 | V35: 劳动纠纷能够从负面视角衡量企业在转型调整过程中劳资关系的稳定程度，是公正转型实施质量的直接佐证。相关数据可通过企业法律纠纷公开记录进行核查，具有较强的可核验性。建议作为可选负向指标纳入体系，与"重大负面舆情"指标共同评价企业在公正转型方面的合规性与社会影响。
C36: 重大负面舆情（负向指标） | D36: 系统性量化企业因“公正转型”措施失当，在公开舆论场引发的负面关注与声誉风险。 关键字： 劳工权益类：转型裁员、安置纠纷、买断工龄、再培训缺失、拖欠补偿金、员工抗议、工会协商破裂； 社区影响类：关停冲击、地方经济衰退、税收锐减、产能退出、搬迁争议、环境遗留问题 过程公正类：决策黑箱、缺乏沟通、无视职工意见、突击式关停、政策套利 | E36: 公正转型原则。应当关注转型可能产生的经济社会影响，并采取措施缓解负面影响。 | G36: 第四条 企业还应当披露本准则第二章至第五章未涵盖的重要的气候相关影响信息。负面舆情可能属于气候相关转型风险中的声誉风险。 | H36: 一（一）2.三是对转型过程中可能产生的经济社会影响，要遵循公正转型原则，做好评估及应对预案。 | J36: 基础指标（一）基本要求。依法依规开展生产经营活动，不存在严重违法违规行为，未列入“严重失信主体名单”，维护行业自律。正常生产，未列入“经营异常名录”。依法依规缴纳税款及社会保险费，按规定支付职工薪酬。不存在从事《中华人民共和国 反垄断法》规定的垄断行为。规范企业公告前，不存在国家有关专项督察通报问题未整改完成事项。 | T36: 来源：公开网络 | U36: 来源：公开网络 | V36: 重大负面舆情是企业公正转型措施失当所引发的社会反应，能够综合反映企业在转型过程中对员工、社区等利益相关方影响的处置质量。舆情信息来源公开，可核验性较强，且能够捕捉到其他定量指标难以覆盖的软性社会影响。建议作为可选负向指标纳入体系，尤其关注与转型行为直接相关的负面事件。
B37: 研发与创新 | C37: 研发投入占比 | D37: 以“研发投入 / 研发费用 / 研究与开发支出”等为核心关键词，结合财务报表附注中“研发支出”相关披露，提取企业当期研发投入金额；分母采用“营业收入”口径计算研发投入占比。 | G37: 第十四条 企业应当披露在生产经营过程中开展的有助于减缓和适应气候变化的创新措施和效果，以及为此支付的成本。 | H37: 一（一）2.技术路径应当具有可行性，要遵循先进性原则。（鼓励技术创新） | I37: 第二十条 披露主体应当积极通过改进工艺、升级生产设备、优化能源结构、提高生产能效、研发和提供绿色产品与服务、改进和强化管理等措施，实现绿色低碳发展，支持美丽中国建设。 第四十二条 （二）开展科技创新的具体情况，包括研发创新管理制度体系建设，参与研发创新、科技合作项目的情况，研发投入金额及占主营业务收入比例、研发人员数量及占比、应用于主营业务的发明专利数量等； | J37: 引领指标——一级指标高端化——二级指标研发投入占比 | K37: 关于用好绿色金融政策支持绿色工厂建设的通知：研发和产业化应用项目。重点支持传统产业绿色低碳重大工艺革新、“卡脖子”技术、短板装备等攻关和产业化应用项目，以及绿色低碳产业新技术新产品新模式研发应用项目。 | T37: 来源：24年可持续发展报告（近三年数据） 附录 1 主要数据指标：产品及客户服务-研发支出：2024年250.12亿元；经济绩效-营业总收入：2024年3,221.16亿元 | U37: 来源：24年可持续发展报告（当年数据和基准年数据） 附录：ESG指标数据-研发创新与知识产权-研发投入 460,234.09万元 | V37: 研发投入占比能够直接反映企业在创新与技术研发方面的资源投入强度，是衡量企业转型能力的重要前瞻性指标。该指标所需数据在企业财务报告中通常具有较好的披露基础，且在多个国内政策框架中被明确列为评价要素。但考虑到部分企业研发投入与低碳技术的直接关联度难以识别，建议作为可选指标，与"节能技改投资占比"配合使用，从不同维度共同衡量企业的转型投入能力。
C38: 科研平台 | D38: 是否具备相应资质的研发中心、技术中心、创新中心、重点实验室等企业科研机构。（自有、母公司或控股的钢铁企业亦可） | G38: 第十四条 企业应当披露在生产经营过程中开展的有助于减缓和适应气候变化的创新措施和效果，以及为此支付的成本。 | H38: 一（一）2.技术路径应当具有可行性，要遵循先进性原则。（鼓励技术创新） | J38: 引领指标——一级指标高端化——二级指标科研平台 | K38: 关于用好绿色金融政策支持绿色工厂建设的通知：研发和产业化应用项目。重点支持传统产业绿色低碳重大工艺革新、“卡脖子”技术、短板装备等攻关和产业化应用项目，以及绿色低碳产业新技术新产品新模式研发应用项目。 | T38: 无明确提及 | U38: 来源：24年可持续发展报告 建立系统、高效、覆盖全公司的低碳技术创新研发协同平台 | V38: 前期设置"科研平台"指标，主要是希望通过企业是否拥有国家级或省级研发机构来评价科研实力。但进一步梳理后发现，该指标更多反映的是历史积累与行政认定结果，与低碳转型动态推进的关联度有限，且不同级别平台之间可比性较差。建议删除该指标，将企业科研能力通过研发投入占比和节能技改投资占比等更具直接性的指标予以体现。
C39: 专利情况 | D39: 以“专利数量、发明专利数量”等关键词为核心，识别分子；分母采用营业收入，计算每单位营收专利拥有量。 | G39: 第十四条 企业应当披露在生产经营过程中开展的有助于减缓和适应气候变化的创新措施和效果，以及为此支付的成本。 | H39: 一（一）2.技术路径应当具有可行性，要遵循先进性原则。（鼓励技术创新） | J39: 引领指标——一级指标高端化——二级指标专利情况 | T39: 来源：24年可持续发展报告 附录 1 主要数据指标：产品及客户服务-有效专利数9,707，应用于主营业务的发明专利数量7,292。 | U39: 来源：24年可持续发展报告（当年数据和基准年数据） 附录：ESG指标数据-研发创新与知识产权-累计专利量2,934个，年度新增授权专利总数476个 | V39: 前期设置"专利情况"指标，主要是希望通过单位营收的专利拥有量来衡量企业技术创新能力。但实际梳理中发现，专利数量受行业属性和战略布局差异影响较大，存量专利与低碳转型技术的关联度难以有效识别，且不同企业专利申请策略和口径差异明显，横向可比性受限。建议删除该指标，转而通过研发投入占比和节能技改投资占比等更聚焦的指标评价企业转型技术投入能力。
C40: 节能技改投资占比 | D40: 以“节能技改 / 技术改造 / 节能改造/超低排放改造投资”等关键词识别企业披露的节能相关技改投资金额，结合“投资金额 / 固定资产投资 / 资本性支出”等表述进行提取；分母统一采用当期营业收入，计算节能技改投资占比。 | E40: 2.转型主体应当制定并披露技术可行的转型计划，主要内容和要求包括： (2)明确每个阶段的工作计划及重点工作任务； 3.转型主体应当制定并披露清晰合理的融资计划，主要内容和要求包括：(2）计划使用的转型金融工具及不同工具筹集资金的主要用途。 | F40: 1. 系统能效提升; 1.1 上升管余热回收 1.2 烧结漏风率综合治理 1.3 水封式烧结环冷机 1.4 烧结返矿冷压球团矿 1.5 球团固固换热显热回收 1.6 高炉大比例球团冶炼 1.7 高炉炉顶均压煤气回收 1.8 转炉一次干法净化回收 1.9 转炉中低温余热回收 1.10 电炉烟气显热回收 1.11 高效煤气发电 1.12 低温余热有机工质朗肯循环（ORC）发电 1.13 电机、变压器、水泵、风机等公辅设施能效提升 4. 环保减排改造： 4.2 颗粒物、SO₂、NOₓ等超低排放改造 | G40: 第十二条（一）业务模式当期和预期的变化，包括其应对气候相关风险和机遇的资源配置（如管理或者退出关于碳、能源或者水密集型业务的计划，因需求或者供应链变化导致的资源配置，通过资本支出或者额外研发支出进行业务发展所产生的资源配置，收购或者剥离等）。 第二十七条（五）资本配置——针对气候相关风险和机遇发生的资本支出、融资或者投资金额。 | H40: 一（一）3.投资活动要在《河北省钢铁行业转型金融支持经济活动目录（2025年版）》范围内（目录中包含重点工序节能提效活动） | I40: 第二十条 披露主体应当积极通过改进工艺、升级生产设备、优化能源结构、提高生产能效、研发和提供绿色产品与服务、改进和强化管理等措施，实现绿色低碳发展，支持美丽中国建设。 第三十五条 （三）能源节约目标以及具体措施，包括但不限于采购节能生产设备、节能照明设备、节能温控设备，采用余热余压利用、能源梯级利用等措施，能源使用存在的具体困难（如有）。 | K40: 关于用好绿色金融政策支持绿色工厂建设的通知：技术改造升级项目。重点支持企业实施节能降碳、节水减污、资源循环利用、清洁原料燃料替代、环保装备升级、数字化绿色化协同升级以及工业绿色微电网、数字化能碳管理中心、绿色数据中心等绿色低碳改造升级项目。 《绿色金融支持项目目录（2025 年版）》：重点工业行业绿色低碳转型，针对钢铁、有色金属、石化化工、建材等高碳排行业，从节能降碳改造和能效提升、工艺改进和流程优化以及数字化、智能化升级三大路径支持工业领域低碳转型，并严格要求单位产品能耗指标值达到最新版《工业重点领域能效标杆水平和基准水平》（2023年版）规定的相应行业产品能效标杆水平。 | M40: CTF：要素1.发行人的气候转型战略和治理：推荐信息和指标：应具体列出实现温室气体减排的主要杠杆，例如详细的资本支出（CapEx）计划及相关技术影响（即计划支出金额、实施此类CapEx项目所考虑的碳成本、运营影响、监管考虑等） CTB：在无法制定范围3温室气体排放KPI/SPT的情况下，发行人可以考虑使用“绿色”资本支出（CapEx）KPI或辅助指标，以展示他们在行业内减少温室气体排放的承诺和进展 | N40: 企业承诺将所有未来资本支出与其长期温室气体目标或《巴黎协定》将全球气温增幅限制在1.5摄氏度的目标保持一致。企业同时必须披露将未来资本支出与其减碳目标相一致的方法。 | O40: 转型投资： 3.3 绿色和脱碳的百分比（占年度投资）；按照企业是否有目标和数据及其器详细程度，并根据降碳数据梯度，分6个评分阈值（0-75%）进行评价； 3.4 绿色脱碳投资比率（绿色转型与脱碳的比值）。按照企业是否有目标和数据及其详细程度，并根据降碳数据梯度，分6个评分阈值（0-75%）进行评价； | T40: 来源：24年可持续发展报告（近三年数据） 2024 年节能低碳投资18.9亿元； 附录 1 主要数据指标：营业总收入3,221.16亿元； | U40: 来源：24年可持续发展报告 节能项目总投资2.3亿元 | V40: 节能技改投资占比直接反映企业在节能降碳技术改造方面的资金投入力度，是衡量企业转型实施进度的核心量化指标之一。相关数据通常在可持续发展报告或企业公告中有所披露，且在国内多个转型金融和行业政策框架中均被明确列为评价要素，具备较好的横向可比性，建议作为转型表现维度的核心量化指标予以保留。
...

Sheet 框架对标结果
A1: 一级指标 | B1: 二级指标 | C1: 三级指标 | D1: 关键字说明 | E1: 人民银行转型金融要求 | F1: 人民银行钢铁行业转型金融标准 | G1: 企业可持续披露准则第1号—气候 | H1: 河北省钢铁转型金融指引 | I1: 沪深北披露指引 | J1: 工信部《钢铁行业规范条件（2025年版）》 | K1: 其他国内政策 | L1: IIGCC | M1: ICMA气候转型债券指引（CTB）和气候转型融资手册（CTF） | N1: TPI | O1: 惠誉常青 | P1: TCFD | Q1: TPT | R1: SASB | S1: GFANZ
A2: 目标与战略 | B2: 目标和承诺 | C2: 碳中和目标 | D2: 企业承诺转型目标与国家碳达峰碳中和目标一致，服务于国家碳达峰碳中和目标；制定减排目标是指企业制定短期（如2024—2025年）、中期（2026—2030年）和长期（至2060年）的目标，且目标符合所在行业的先进性水平 | E2: ✔ | G2: ✔ | H2: ✔ | L2: ✔ | M2: ✔ | N2: ✔ | O2: ✔ | P2: ✔ | Q2: ✔ | R2: ✔ | S2: ✔
C3: 碳达峰目标 | D3: 企业承诺转型目标与国家碳达峰碳中和目标一致，服务于国家碳达峰碳中和目标；制定减排目标是指企业制定短期（如2024—2025年）、中期（2026—2030年）和长期（至2060年）的目标，且目标符合所在行业的先进性水平 | E3: ✔ | G3: ✔ | H3: ✔ | L3: ✔ | M3: ✔ | N3: ✔ | O3: ✔ | P3: ✔ | Q3: ✔ | R3: ✔ | S3: ✔
C4: 其他环境目标 | D4: 指除碳达峰 / 碳中和目标之外，用于支撑低碳转型路径落地的能效、资源、污染与过程优化类目标。 可识别目标类型包括但不限于： 1. 能效提升（如吨钢综合能耗下降） 2. 能源结构优化（如清洁电力占比、余热利用） 3. 污染物减排（SO₂ / NOx / PM / VOCs） 4. 水资源管理（吨钢取水量、回用率） 5. 资源循环与废弃物（废钢比、固废利用率） 6. 工艺与流程优化（短流程占比、关键工序效率） | E4: ✔ | G4: ✔ | I4: ✔ | L4: ✔ | M4: ✔ | N4: ✔ | Q4: ✔
B5: 战略和规划 | C5: 转型规划 | D5: 企业制定明确的转型路线图、行动方案或分阶段规划 | E5: ✔ | G5: ✔ | H5: ✔ | I5: ✔ | L5: ✔ | M5: ✔ | N5: ✔ | O5: ✔ | P5: ✔ | Q5: ✔ | R5: ✔ | S5: ✔
C6: 其他战略 | D6: 企业如尚未制定专门的转型规划，是否已建立低碳与可持续治理的制度与行动框架 | I6: ✔ | S6: ✔
A7: 实施保障 | B7: 治理 | C7: 治理架构 | D7: 企业围绕低碳/绿色/可持续/转型/ESG议题建立的治理层级完整性与权责清晰度 | E7: ✔ | G7: ✔ | H7: ✔ | I7: ✔ | L7: ✔ | M7: ✔ | N7: ✔ | P7: ✔ | Q7: ✔ | S7: ✔
B8: 风险管理 | C8: 气候风险管理体系 | D8: 1. 全面风险嵌入（ERM化）：将气候风险由单一环保议题上升为公司级战略风险，实质性嵌入ERM及全价值链决策流程。 2. 治理架构多级化：构建“董事会—管理层—执行层”的三级或四级垂直穿透式治理架构。 3. 管控手段数智化：建设并运行“智能气候风险管理信息系统”或数字化管理平台，实现风险数据的常态化监测与可视化。 4. 责任落实绩效化：形成“目标—执行—考核—追责”闭环，并将气候/碳相关指标刚性挂钩领导班子或管理层年度经营业绩评价。 | G8: ✔ | H8: ✔ | I8: ✔ | L8: ✔ | N8: ✔ | P8: ✔ | R8: ✔
C9: 气候相关风险和机遇 | D9: 1. 风险与机遇识别完整性：同时识别转型风险与实体风险，涵盖政策/法律、技术、市场、供应链、声誉、急性与慢性物理风险等；同时识别低碳产品、能源结构优化、政策支持等机遇。 2. 时间维度清晰性：在短期（1–2年）、中期（3–6年）、长期（7年及以上）不同时间框架下开展识别与评估。 3. 财务影响关联性：识别风险和机遇对成本、收入、投资、融资、信用风险等财务事项的影响。 4. 量化深度差异：区分定性判断、间接量化（环保投入、节能降本）与直接量化（营收变化、成本变化、溢价比例、履约成本节约等）。 | G9: ✔ | I9: ✔ | L9: ✔ | M9: ✔ | N9: ✔ | P9: ✔
C10: 气候压力测试 | D10: 1. 开展情况：明确披露已开展气候情景分析或压力测试。 2. 情景设置特征：情景覆盖转型风险与实体风险，包含中长期时间尺度。 3. 方法论来源：参考国际或行业权威情景与框架（如 IFRS S2、IEA、IPCC、钢铁行业低碳转型情景）。 4. 结果应用：情景分析结果用于评估对经营、成本、收入、资产或融资的潜在影响，并支撑风险管理或战略判断。 | G10: ✔ | H10: ✔ | I10: ✔ | L10: ✔ | N10: ✔ | P10: ✔
C11: 环境行政处罚（负向指标） | D11: 衡量企业在战略转型期（如前/后3年）因环境违法行为受到地方监管部门行政处罚的严重程度。 | E11: ✔ | G11: ✔ | H11: ✔ | I11: ✔ | J11: ✔
C12: 安全生产行政处罚（负向指标） | D12: 衡量企业因违反安全生产法规受到处罚或发生生产安全责任事故的严重程度 | G12: ✔ | I12: ✔ | J12: ✔ | R12: ✔
C13: 失信事件管理（负向指标） | D13: 量化转型期企业面临的诉讼压力与现金流风险，案件常涉及合同（供应链）、劳动（安置）、金融（偿债）纠纷。 | G13: ✔ | I13: ✔ | J13: ✔
A14: 转型表现 | B14: 碳排放表现 | C14: 碳价敏感度 | D14: 采用季度或年度报告等口径中披露的EBITDA（税息折旧及摊销前利润）、市场碳价等业务、财务数据，形成理论碳成本占企业经营利润的比例，衡量企业盈利对碳价（尤其是潜在或未来碳价格）的敏感程度。 | G14: ✔ | K14: ✔
C15: 碳排放披露情况 | D15: 1. 核心词：范围1、直接排放、范围2、能源间接排放、范围3、价值链排放 2. 范围3类别词：类别1、采购商品、上下游运输、差旅、员工通勤、废弃物 | E15: ✔ | G15: ✔ | H15: ✔ | I15: ✔ | K15: ✔ | L15: ✔ | N15: ✔ | R15: ✔
C16: 物理碳排放强度 | D16: 单位粗钢产量所产生的范围一和范围二的碳排放量 | E16: ✔ | G16: ✔ | H16: ✔ | K16: ✔ | L16: ✔ | M16: ✔ | O16: ✔ | P16: ✔ | R16: ✔
C17: 营收碳排放强度 | D17: 单位营业收入所产生的范围一和范围二的碳排放量 | E17: ✔ | G17: ✔ | M17: ✔
B18: 其他环境表现 | C18: 可再生能源占比 | D18: 自发可再生能源电量，是指企业在自身生产经营边界内，通过自建或控股的可再生能源发电设施，所产生并被企业自身消费的电力。 能源消耗总量：企业当期披露的能源消耗总量（单位 MWh） | F18: ✔ | G18: ✔ | H18: ✔ | I18: ✔ | K18: ✔ | M18: ✔ | R18: ✔
D19: 外购绿电包括： 绿电交易电量 绿证对应电量（如披露） 能源消耗总量：企业当期披露的能源消耗总量（单位 MWh） | G19: ✔ | R19: ✔
C20: 用水效率 | D20: 单位粗钢水消耗量，指企业在生产过程中对水资源的消耗情况 用水效率 = 当期总用水量 ÷ 当期粗钢产量 | E20: ✔ | G20: ✔ | H20: ✔ | I20: ✔ | J20: ✔ | R20: ✔
C21: 生物多样性 | D21: 企业在生物多样性保护方面表现，比如制度或组织架构建设、具体措施和实际成效，包括保护区域的生态恢复、物种多样性保护及生态环境修复等。 | E21: ✔ | G21: ✔ | H21: ✔ | I21: ✔
B22: 公正转型 | C22: 员工培训 | D22: 本指标用于评估企业是否关注并投入员工能力建设，尤其是在转型相关技能方面。 考虑到企业披露口径差异较大，本指标采用是否类累加赋分方式，不对不同披露口径进行强制可比性要求。 | E22: ✔ | G22: ✔ | H22: ✔ | I22: ✔ | Q22: ✔ | S22: ✔
C23: 稳就业与促就业 | D23: 衡量企业在转型过程中是否避免通过大规模裁员转嫁成本，并通过稳定或扩大就业规模，体现对劳动者和社会的责任承担。 | E23: ✔ | G23: ✔ | H23: ✔ | I23: ✔ | Q23: ✔
C24: 劳动纠纷（负向指标） | D24: 衡量因转型调整（如岗位重组、合同解除）引发的、并已进入正式法律或仲裁程序的劳资纠纷数量与严重性。 案由关键字：船员劳务合同纠纷、辞退争议、经济性裁员争议、劳动合同纠纷、劳动争议、劳务合同纠纷、离退休人员返聘合同纠纷、确认劳动关系纠纷、社会保险纠纷、职工破产债权确认纠纷、追索劳动报酬纠纷 | E24: ✔ | G24: ✔ | H24: ✔ | I24: ✔
C25: 重大负面舆情（负向指标） | D25: 系统性量化企业因“公正转型”措施失当，在公开舆论场引发的负面关注与声誉风险。 关键字： 劳工权益类：转型裁员、安置纠纷、买断工龄、再培训缺失、拖欠补偿金、员工抗议、工会协商破裂； 社区影响类：关停冲击、地方经济衰退、税收锐减、产能退出、搬迁争议、环境遗留问题 过程公正类：决策黑箱、缺乏沟通、无视职工意见、突击式关停、政策套利 | E25: ✔ | G25: ✔ | H25: ✔
B26: 研发与创新 | C26: 研发投入占比 | D26: 以“研发投入 / 研发费用 / 研究与开发支出”等为核心关键词，结合财务报表附注中“研发支出”相关披露，提取企业当期研发投入金额；分母采用“营业收入”口径计算研发投入占比。 | G26: ✔ | H26: ✔ | I26: ✔ | J26: ✔ | K26: ✔
C27: 节能技改投资占比 | D27: 以“节能技改 / 技术改造 / 节能改造/超低排放改造投资”等关键词识别企业披露的节能相关技改投资金额，结合“投资金额 / 固定资产投资 / 资本性支出”等表述进行提取；分母统一采用当期营业收入，计算节能技改投资占比。 | E27: ✔ | F27: ✔ | G27: ✔ | H27: ✔ | I27: ✔ | K27: ✔ | M27: ✔ | N27: ✔ | O27: ✔
C28: 环保投入金额占比 | D28: 以“环保投入 / 环保投资 / 环境保护支出”等关键词为核心，识别企业披露的污染防治、环保设施及相关投入金额；分母采用营业收入，计算环保投入占比。 | E28: ✔ | H28: ✔ | I28: ✔
B29: 行业特定 | C29: 超低排放改造进程 | D29: 超低排放改造进程=（SOx排放量+NOx排放量+颗粒物排放量）/当年粗钢产量​ 超低排放改造是指对工业生产过程中的重点行业（如火电、钢铁、水泥、焦化等）实施全面的大气污染治理升级改造，旨在使企业生产过程中产生的大气污染物排放浓度达到极低水平，接近或低于天然气燃气轮机组的排放标准。 具体而言，超低排放改造的核心目标是通过技术手段，对生产环节中的有组织排放（如烟囱排放）、无组织排放（如物料储存、输送过程中的逸散）以及运输环节的污染物排放进行严格控制，实现颗粒物、二氧化硫、氮氧化物等主要污染物排放浓度显著降低。 | E29: ✔ | F29: ✔ | G29: ✔ | H29: ✔ | I29: ✔ | J29: ✔ | K29: ✔ | R29: ✔
C30: 系统能效提升 | D30: 企业通过全流程深度优化与多种相关技术手段协同提升能源利用效率，从而降低单位产出能耗和碳排放，最终使能源利用效率达到行业最优甚至接近极限水平。包括相关节能降碳技术与“极致能效”称号。 | F30: ✔ | G30: ✔ | H30: ✔ | K30: ✔ | R30: ✔
C31: 环保减排改造 | D31: 企业通过系统性工程改造与全国全过程控制，使污染物排放水平大幅低于常规标准，实现钢铁等高排放行业的深度环境治理与绿色转型。主要包括超低排放改造完成情况。 | F31: ✔ | G31: ✔ | H31: ✔ | K31: ✔ | R31: ✔
C32: 冶炼技术突破 | D32: 企业通过开发和应用前沿性关键低碳冶炼技术，改变传统高碳生产路径。包括氢冶金、CCUS、电炉短流程炼钢等前沿技术。 | F32: ✔ | G32: ✔ | H32: ✔ | K32: ✔ | R32: ✔
C33: 数字化赋能 | D33: 企业在智能制造方面的相关表现，包括人工智能应用、数字化工厂、工业互联网、物联网等。 | F33: ✔ | G33: ✔ | H33: ✔ | K33: ✔ | R33: ✔
C34: 产品结构优化 | D34: 企业通过调整产品类型与生产结构，用更高性能、更高附加值、更低碳的产品替代高消耗、低性能、低附加值的传统产品。主要包括高端产品布局与质量奖等。 | F34: ✔ | G34: ✔ | H34: ✔ | K34: ✔ | R34: ✔
C35: 废钢回收率 | D35: 衡量企业利用废钢资源的效率，包括内部回收和社会回收的废钢量占总粗钢产量的比例。 | F35: ✔ | G35: ✔ | H35: ✔ | K35: ✔ | R35: ✔
A36: 未入选指标
A37: 一级指标 | B37: 二级指标 | C37: 三级指标 | D37: 关键字说明
A38: 实施保障 | B38: 转型举措 | C38: 自身减排措施 | D38: 企业为实现低碳转型与应对气候变化，当前已实施或计划实施的关键减排与转型措施，包括发生在企业自身运营与资产层面的直接措施。 | E38: ✔ | G38: ✔ | I38: ✔ | L38: ✔ | N38: ✔ | O38: ✔ | Q38: ✔ | S38: ✔
C39: 供应链减排措施 | D39: 企业为实现低碳转型与应对气候变化，当前已实施或计划实施的关键减排与转型措施，包括通过价值链协同实现的间接措施。 | E39: ✔ | G39: ✔ | I39: ✔ | L39: ✔ | Q39: ✔ | R39: ✔ | S39: ✔
B40: 治理 | C40: 薪酬激励 | D40: ESG/可持续发展/低碳/转型目标是否通过绩效与薪酬机制转化为真实的管理激励与约束 | E40: ✔ | G40: ✔ | L40: ✔ | N40: ✔ | O40: ✔ | P40: ✔ | Q40: ✔ | S40: ✔
...

Sheet 正向指标
A1: 一级指标 | B1: 二级指标 | C1: 三级指标 | D1: 关键字说明 | E1: 分值关系 | F1: 指标因子 | G1: 问题 | H1: 判断依据/计算公式 | I1: 分档 | J1: 对应分值 | K1: 空值处理 | L1: 数据长度 | M1: 必填 | N1: 获取频度 | O1: 数据粒度 | P1: 参考数据 | Q1: 技术校验规则 | R1: 业务校验规则 | S1: 数据来源 | T1: 数据来源接口 | U1: 备注 | V1: 比重系数
A2: 目标与战略（25分） | B2: 目标和承诺 | C2: 碳中和目标 | D2: 企业承诺转型目标与国家碳达峰碳中和目标一致，服务于国家碳达峰碳中和目标；制定减排目标是指企业制定短期（如2024-2025年）、中期（2026-2030年）和长期（至2060年）的目标，且目标符合所在行业的先进性水平 | E2: 相等 | F2: 中和年份承诺与覆盖度 | H2: 计算原始得分 = 基础分 × 范围系数 1. 基础分（时间维度） 若无目标或年份 > 2060：0 分 若年份 ≤ 2050：10 分 若 2050 < 年份 ≤ 2060： 基础分 = 10 − 0.4 × (年份 − 2050) （说明：每晚 1 年扣 0.4 分，2060 年得 6 分） 2. 范围系数 仅覆盖部分区域 / 子公司 / 单一工序范围1：0.5 仅覆盖部分区域 / 子公司 / 单一工序范围1+2：0.6 覆盖部分区域 / 子公司 / 单一工序范围1+2+3：0.7 覆盖全集团范围 1：0.8 覆盖全集团范围 1+2：1 覆盖全集团范围 1+2+3（含重要供应链）：1.2 对计算结果做0-12的分布 | I2: 0 | J2: 0 | K2: 适用规则A（强制-赋0） | S2: 公司可持续发展报告 | V2: 1
I3: (0, 3] | J3: 2.5
I4: (3, 6] | J4: 5
I5: (6, 9] | J5: 7.5
I6: (9, 12] | J6: 10
C7: 碳达峰目标 | D7: 企业承诺转型目标与国家碳达峰碳中和目标一致，服务于国家碳达峰碳中和目标；制定减排目标是指企业制定短期（如2024-2025年）、中期（2026-2030年）和长期（至2060年）的目标，且目标符合所在行业的先进性水平 | E7: 相等 | F7: 达峰年份承诺与覆盖度 | H7: 计算原始得分 = 基础分 × 范围系数 1. 基础分（时间维度，0–10 分） 无目标：0分 承诺年份 > 2030：3 分 承诺年份=2030，6分 承诺年份 ≤ 2025 或已明确达峰：10 分 2025 < 年份 ≤ 2030： 基础分 = 10 − 0.8 × (年份 − 2025) （说明：2030 年达峰得 6 分，每提前 1 年加 0.8 分） 2. 范围系数 仅覆盖部分区域 / 子公司 / 单一工序范围1：0.5 仅覆盖部分区域 / 子公司 / 单一工序范围1+2：0.6 覆盖部分区域 / 子公司 / 单一工序范围1+2+3：0.7 覆盖全集团范围 1：0.8 覆盖全集团范围 1+2：1 覆盖全集团范围 1+2+3（含重要供应链）：1.2 对计算结果做0-12的分布 | I7: 0 | J7: 0 | K7: 适用规则A（强制-赋0） | S7: 公司可持续发展报告、公开网络信息 | V7: 0.9
I8: (0, 3] | J8: 2.5
I9: (3, 6] | J9: 5
I10: (6, 9] | J10: 7.5
I11: (9, 12] | J11: 10
