Workbook

Sheet 统一打分计算
A1: 指标 | B1: 企业 | C1: 当期值 | D1: 基准值 | E1: 改进率/提升率 | F1: 行业维度得分(S_ind) | G1: 自身维度得分(S_self) | H1: 总分
A2: 物理碳排放 | B2: 中信特钢 | C2: 1.766369 | D2: 1.949144 | E2: 0.093771912 | F2: =IF(ISBLANK(C2),0,IF(C2<=参数底稿!$E$2,10,IF(C2>=参数底稿!$F$2,1,1+9*(参数底稿!$F$2-C2)/(参数底稿!$F$2-参数底稿!$E$2)))) -> 6.5301749 | G2: =IF(ISBLANK(E2),0,IF(E2>=参数底稿!$F$3,10,IF(E2<=参数底稿!$E$3,1,1+9*(E2-参数底稿!$E$3)/(参数底稿!$F$3-参数底稿!$E$3)))) -> 10 | H2: =0.7*F2+0.3*G2 -> 7.5711225
A3: 物理碳排放 | B3: 柳钢股份 | C3: 1.0822139 | D3: 1.1559959 | E3: 0.063825546 | F3: =IF(ISBLANK(C3),0,IF(C3<=参数底稿!$E$2,10,IF(C3>=参数底稿!$F$2,1,1+9*(参数底稿!$F$2-C3)/(参数底稿!$F$2-参数底稿!$E$2)))) -> 10 | G3: =IF(ISBLANK(E3),0,IF(E3>=参数底稿!$F$3,10,IF(E3<=参数底稿!$E$3,1,1+9*(E3-参数底稿!$E$3)/(参数底稿!$F$3-参数底稿!$E$3)))) -> 10 | H3: =0.7*F3+0.3*G3 -> 10
A4: 物理碳排放 | B4: 杭钢股份 | C4: 2.030303 | D4: 2.1084071 | E4: 0.037044103 | F4: =IF(ISBLANK(C4),0,IF(C4<=参数底稿!$E$2,10,IF(C4>=参数底稿!$F$2,1,1+9*(参数底稿!$F$2-C4)/(参数底稿!$F$2-参数底稿!$E$2)))) -> 2.4998417 | G4: =IF(ISBLANK(E4),0,IF(E4>=参数底稿!$F$3,10,IF(E4<=参数底稿!$E$3,1,1+9*(E4-参数底稿!$E$3)/(参数底稿!$F$3-参数底稿!$E$3)))) -> 8.4112969 | H4: =0.7*F4+0.3*G4 -> 4.2732783
A5: 物理碳排放 | B5: 太钢不锈 | C5: 1.6047041 | D5: 1.6552771 | E5: 0.030552617 | F5: =IF(ISBLANK(C5),0,IF(C5<=参数底稿!$E$2,10,IF(C5>=参数底稿!$F$2,1,1+9*(参数底稿!$F$2-C5)/(参数底稿!$F$2-参数底稿!$E$2)))) -> 8.9988363 | G5: =IF(ISBLANK(E5),0,IF(E5>=参数底稿!$F$3,10,IF(E5<=参数底稿!$E$3,1,1+9*(E5-参数底稿!$E$3)/(参数底稿!$F$3-参数底稿!$E$3)))) -> 7.9299389 | H5: =0.7*F5+0.3*G5 -> 8.6781671
A6: 物理碳排放 | B6: 宝山钢铁 | C6: 2.1443299 | D6: 2.1852137 | E6: 0.018709297 | F6: =IF(ISBLANK(C6),0,IF(C6<=参数底稿!$E$2,10,IF(C6>=参数底稿!$F$2,1,1+9*(参数底稿!$F$2-C6)/(参数底稿!$F$2-参数底稿!$E$2)))) -> 1 | G6: =IF(ISBLANK(E6),0,IF(E6>=参数底稿!$F$3,10,IF(E6<=参数底稿!$E$3,1,1+9*(E6-参数底稿!$E$3)/(参数底稿!$F$3-参数底稿!$E$3)))) -> 7.0517308 | H6: =0.7*F6+0.3*G6 -> 2.8155192
A7: 物理碳排放 | B7: 河钢股份 | C7: 2.0457986 | D7: 2.0799527 | E7: 0.016420613 | F7: =IF(ISBLANK(C7),0,IF(C7<=参数底稿!$E$2,10,IF(C7>=参数底稿!$F$2,1,1+9*(参数底稿!$F$2-C7)/(参数底稿!$F$2-参数底稿!$E$2)))) -> 2.2632202 | G7: =IF(ISBLANK(E7),0,IF(E7>=参数底稿!$F$3,10,IF(E7<=参数底稿!$E$3,1,1+9*(E7-参数底稿!$E$3)/(参数底稿!$F$3-参数底稿!$E$3)))) -> 6.8820199 | H7: =0.7*F7+0.3*G7 -> 3.6488601
A8: 物理碳排放 | B8: 中南股份 | C8: 1.8107417 | D8: 1.8204489 | E8: 0.0053323056 | F8: =IF(ISBLANK(C8),0,IF(C8<=参数底稿!$E$2,10,IF(C8>=参数底稿!$F$2,1,1+9*(参数底稿!$F$2-C8)/(参数底稿!$F$2-参数底稿!$E$2)))) -> 5.8525944 | G8: =IF(ISBLANK(E8),0,IF(E8>=参数底稿!$F$3,10,IF(E8<=参数底稿!$E$3,1,1+9*(E8-参数底稿!$E$3)/(参数底稿!$F$3-参数底稿!$E$3)))) -> 6.0597976 | H8: =0.7*F8+0.3*G8 -> 5.9147554
A9: 物理碳排放 | B9: 重庆钢铁 | C9: 1.5256242 | D9: 1.5303327 | E9: 0.0030767835 | F9: =IF(ISBLANK(C9),0,IF(C9<=参数底稿!$E$2,10,IF(C9>=参数底稿!$F$2,1,1+9*(参数底稿!$F$2-C9)/(参数底稿!$F$2-参数底稿!$E$2)))) -> 10 | G9: =IF(ISBLANK(E9),0,IF(E9>=参数底稿!$F$3,10,IF(E9<=参数底稿!$E$3,1,1+9*(E9-参数底稿!$E$3)/(参数底稿!$F$3-参数底稿!$E$3)))) -> 5.8925457 | H9: =0.7*F9+0.3*G9 -> 8.7677637
A10: 物理碳排放 | B10: 首钢股份 | C10: 1.8982833 | D10: 1.8973253 | E10: -0.00050491152 | F10: =IF(ISBLANK(C10),0,IF(C10<=参数底稿!$E$2,10,IF(C10>=参数底稿!$F$2,1,1+9*(参数底稿!$F$2-C10)/(参数底稿!$F$2-参数底稿!$E$2)))) -> 4.5158143 | G10: =IF(ISBLANK(E10),0,IF(E10>=参数底稿!$F$3,10,IF(E10<=参数底稿!$E$3,1,1+9*(E10-参数底稿!$E$3)/(参数底稿!$F$3-参数底稿!$E$3)))) -> 5.6269551 | H10: =0.7*F10+0.3*G10 -> 4.8491565
A11: 物理碳排放 | B11: 山东钢铁 | C11: 1.8199595 | D11: 1.8180602 | E11: -0.0010447073 | F11: =IF(ISBLANK(C11),0,IF(C11<=参数底稿!$E$2,10,IF(C11>=参数底稿!$F$2,1,1+9*(参数底稿!$F$2-C11)/(参数底稿!$F$2-参数底稿!$E$2)))) -> 5.7118357 | G11: =IF(ISBLANK(E11),0,IF(E11>=参数底稿!$F$3,10,IF(E11<=参数底稿!$E$3,1,1+9*(E11-参数底稿!$E$3)/(参数底稿!$F$3-参数底稿!$E$3)))) -> 5.5869281 | H11: =0.7*F11+0.3*G11 -> 5.6743634
A12: 物理碳排放 | B12: 新钢股份 | C12: 2.0916415 | D12: 1.9815838 | E12: -0.055540269 | F12: =IF(ISBLANK(C12),0,IF(C12<=参数底稿!$E$2,10,IF(C12>=参数底稿!$F$2,1,1+9*(参数底稿!$F$2-C12)/(参数底稿!$F$2-参数底稿!$E$2)))) -> 1.5631892 | G12: =IF(ISBLANK(E12),0,IF(E12>=参数底稿!$F$3,10,IF(E12<=参数底稿!$E$3,1,1+9*(E12-参数底稿!$E$3)/(参数底稿!$F$3-参数底稿!$E$3)))) -> 1.5459627 | H12: =0.7*F12+0.3*G12 -> 1.5580212
A13: 物理碳排放 | B13: 马钢股份 | C13: 2.0076253 | D13: 1.885548 | E13: -0.06474365 | F13: =IF(ISBLANK(C13),0,IF(C13<=参数底稿!$E$2,10,IF(C13>=参数底稿!$F$2,1,1+9*(参数底稿!$F$2-C13)/(参数底稿!$F$2-参数底稿!$E$2)))) -> 2.8461364 | G13: =IF(ISBLANK(E13),0,IF(E13>=参数底稿!$F$3,10,IF(E13<=参数底稿!$E$3,1,1+9*(E13-参数底稿!$E$3)/(参数底稿!$F$3-参数底稿!$E$3)))) -> 1 | H13: =0.7*F13+0.3*G13 -> 2.2922955
A14: 物理碳排放 | B14: 南钢股份 | C14: 2.1898598 | D14: 1.9855769 | E14: -0.10288337 | F14: =IF(ISBLANK(C14),0,IF(C14<=参数底稿!$E$2,10,IF(C14>=参数底稿!$F$2,1,1+9*(参数底稿!$F$2-C14)/(参数底稿!$F$2-参数底稿!$E$2)))) -> 1 | G14: =IF(ISBLANK(E14),0,IF(E14>=参数底稿!$F$3,10,IF(E14<=参数底稿!$E$3,1,1+9*(E14-参数底稿!$E$3)/(参数底稿!$F$3-参数底稿!$E$3)))) -> 1 | H14: =0.7*F14+0.3*G14 -> 1
A15: 物理碳排放 | B15: 宝武钢铁 | F15: =IF(ISBLANK(C15),0,IF(C15<=参数底稿!$E$2,10,IF(C15>=参数底稿!$F$2,1,1+9*(参数底稿!$F$2-C15)/(参数底稿!$F$2-参数底稿!$E$2)))) -> 0 | G15: =IF(ISBLANK(E15),0,IF(E15>=参数底稿!$F$3,10,IF(E15<=参数底稿!$E$3,1,1+9*(E15-参数底稿!$E$3)/(参数底稿!$F$3-参数底稿!$E$3)))) -> 0 | H15: =0.7*F15+0.3*G15 -> 0
A16: 物理碳排放 | B16: 华菱钢铁 | F16: =IF(ISBLANK(C16),0,IF(C16<=参数底稿!$E$2,10,IF(C16>=参数底稿!$F$2,1,1+9*(参数底稿!$F$2-C16)/(参数底稿!$F$2-参数底稿!$E$2)))) -> 0 | G16: =IF(ISBLANK(E16),0,IF(E16>=参数底稿!$F$3,10,IF(E16<=参数底稿!$E$3,1,1+9*(E16-参数底稿!$E$3)/(参数底稿!$F$3-参数底稿!$E$3)))) -> 0 | H16: =0.7*F16+0.3*G16 -> 0
A17: 物理碳排放 | B17: 包钢股份 | F17: =IF(ISBLANK(C17),0,IF(C17<=参数底稿!$E$2,10,IF(C17>=参数底稿!$F$2,1,1+9*(参数底稿!$F$2-C17)/(参数底稿!$F$2-参数底稿!$E$2)))) -> 0 | G17: =IF(ISBLANK(E17),0,IF(E17>=参数底稿!$F$3,10,IF(E17<=参数底稿!$E$3,1,1+9*(E17-参数底稿!$E$3)/(参数底稿!$F$3-参数底稿!$E$3)))) -> 0 | H17: =0.7*F17+0.3*G17 -> 0
A18: 物理碳排放 | B18: 鞍钢股份 | F18: =IF(ISBLANK(C18),0,IF(C18<=参数底稿!$E$2,10,IF(C18>=参数底稿!$F$2,1,1+9*(参数底稿!$F$2-C18)/(参数底稿!$F$2-参数底稿!$E$2)))) -> 0 | G18: =IF(ISBLANK(E18),0,IF(E18>=参数底稿!$F$3,10,IF(E18<=参数底稿!$E$3,1,1+9*(E18-参数底稿!$E$3)/(参数底稿!$F$3-参数底稿!$E$3)))) -> 0 | H18: =0.7*F18+0.3*G18 -> 0
A19: 物理碳排放 | B19: 本钢板材 | F19: =IF(ISBLANK(C19),0,IF(C19<=参数底稿!$E$2,10,IF(C19>=参数底稿!$F$2,1,1+9*(参数底稿!$F$2-C19)/(参数底稿!$F$2-参数底稿!$E$2)))) -> 0 | G19: =IF(ISBLANK(E19),0,IF(E19>=参数底稿!$F$3,10,IF(E19<=参数底稿!$E$3,1,1+9*(E19-参数底稿!$E$3)/(参数底稿!$F$3-参数底稿!$E$3)))) -> 0 | H19: =0.7*F19+0.3*G19 -> 0
A20: 物理碳排放 | B20: 八一钢铁 | C20: 1.5706806 | F20: =IF(ISBLANK(C20),0,IF(C20<=参数底稿!$E$2,10,IF(C20>=参数底稿!$F$2,1,1+9*(参数底稿!$F$2-C20)/(参数底稿!$F$2-参数底稿!$E$2)))) -> 9.5183826 | G20: =IF(ISBLANK(E20),0,IF(E20>=参数底稿!$F$3,10,IF(E20<=参数底稿!$E$3,1,1+9*(E20-参数底稿!$E$3)/(参数底稿!$F$3-参数底稿!$E$3)))) -> 0 | H20: =0.7*F20+0.3*G20 -> 6.6628678
A21: 物理碳排放 | B21: 凌钢股份 | F21: =IF(ISBLANK(C21),0,IF(C21<=参数底稿!$E$2,10,IF(C21>=参数底稿!$F$2,1,1+9*(参数底稿!$F$2-C21)/(参数底稿!$F$2-参数底稿!$E$2)))) -> 0 | G21: =IF(ISBLANK(E21),0,IF(E21>=参数底稿!$F$3,10,IF(E21<=参数底稿!$E$3,1,1+9*(E21-参数底稿!$E$3)/(参数底稿!$F$3-参数底稿!$E$3)))) -> 0 | H21: =0.7*F21+0.3*G21 -> 0
A23: 营收碳排放 | B23: 杭钢股份 | C23: 1.3681201 | D23: 1.7070593 | E23: 0.19855149 | F23: =IF(ISBLANK(C23),0,IF(C23<=参数底稿!$E$5,10,IF(C23>=参数底稿!$F$5,1,1+9*(参数底稿!$F$5-C23)/(参数底稿!$F$5-参数底稿!$E$5)))) -> 10 | G23: =IF(ISBLANK(E23),0,IF(E23>=参数底稿!$F$6,10,IF(E23<=参数底稿!$E$6,1,1+9*(E23-参数底稿!$E$6)/(参数底稿!$F$6-参数底稿!$E$6)))) -> 10 | H23: =0.7*F23+0.3*G23 -> 10
A24: 营收碳排放 | B24: 中信特钢 | C24: 3.2608994 | D24: 3.3950482 | E24: 0.039513067 | F24: =IF(ISBLANK(C24),0,IF(C24<=参数底稿!$E$5,10,IF(C24>=参数底稿!$F$5,1,1+9*(参数底稿!$F$5-C24)/(参数底稿!$F$5-参数底稿!$E$5)))) -> 6.5342964 | G24: =IF(ISBLANK(E24),0,IF(E24>=参数底稿!$F$6,10,IF(E24<=参数底稿!$E$6,1,1+9*(E24-参数底稿!$E$6)/(参数底稿!$F$6-参数底稿!$E$6)))) -> 10 | H24: =0.7*F24+0.3*G24 -> 7.5740075
A25: 营收碳排放 | B25: 柳钢股份 | C25: 2.8717276 | D25: 2.8557083 | E25: -0.0056095789 | F25: =IF(ISBLANK(C25),0,IF(C25<=参数底稿!$E$5,10,IF(C25>=参数底稿!$F$5,1,1+9*(参数底稿!$F$5-C25)/(参数底稿!$F$5-参数底稿!$E$5)))) -> 7.9932427 | G25: =IF(ISBLANK(E25),0,IF(E25>=参数底稿!$F$6,10,IF(E25<=参数底稿!$E$6,1,1+9*(E25-参数底稿!$E$6)/(参数底稿!$F$6-参数底稿!$E$6)))) -> 8.6007941 | H25: =0.7*F25+0.3*G25 -> 8.1755082
A26: 营收碳排放 | B26: 太钢不锈 | C26: 2.1070144 | D26: 2.0640421 | E26: -0.020819489 | F26: =IF(ISBLANK(C26),0,IF(C26<=参数底稿!$E$5,10,IF(C26>=参数底稿!$F$5,1,1+9*(参数底稿!$F$5-C26)/(参数底稿!$F$5-参数底稿!$E$5)))) -> 10 | G26: =IF(ISBLANK(E26),0,IF(E26>=参数底稿!$F$6,10,IF(E26<=参数底稿!$E$6,1,1+9*(E26-参数底稿!$E$6)/(参数底稿!$F$6-参数底稿!$E$6)))) -> 8.0112475 | H26: =0.7*F26+0.3*G26 -> 9.4033743
A27: 营收碳排放 | B27: 河钢股份 | C27: 4.44428 | D27: 4.3024506 | E27: -0.032964786 | F27: =IF(ISBLANK(C27),0,IF(C27<=参数底稿!$E$5,10,IF(C27>=参数底稿!$F$5,1,1+9*(参数底稿!$F$5-C27)/(参数底稿!$F$5-参数底稿!$E$5)))) -> 2.0979816 | G27: =IF(ISBLANK(E27),0,IF(E27>=参数底稿!$F$6,10,IF(E27<=参数底稿!$E$6,1,1+9*(E27-参数底稿!$E$6)/(参数底稿!$F$6-参数底稿!$E$6)))) -> 7.5404874 | H27: =0.7*F27+0.3*G27 -> 3.7307333
A28: 营收碳排放 | B28: 宝山钢铁 | C28: 3.4223696 | D28: 3.2911143 | E28: -0.03988172 | F28: =IF(ISBLANK(C28),0,IF(C28<=参数底稿!$E$5,10,IF(C28>=参数底稿!$F$5,1,1+9*(参数底稿!$F$5-C28)/(参数底稿!$F$5-参数底稿!$E$5)))) -> 5.9289692 | G28: =IF(ISBLANK(E28),0,IF(E28>=参数底稿!$F$6,10,IF(E28<=参数底稿!$E$6,1,1+9*(E28-参数底稿!$E$6)/(参数底稿!$F$6-参数底稿!$E$6)))) -> 7.2723822 | H28: =0.7*F28+0.3*G28 -> 6.3319931
A29: 营收碳排放 | B29: 首钢股份 | C29: 4.0836111 | D29: 3.8659998 | E29: -0.056288496 | F29: =IF(ISBLANK(C29),0,IF(C29<=参数底稿!$E$5,10,IF(C29>=参数底稿!$F$5,1,1+9*(参数底稿!$F$5-C29)/(参数底稿!$F$5-参数底稿!$E$5)))) -> 3.4500748 | G29: =IF(ISBLANK(E29),0,IF(E29>=参数底稿!$F$6,10,IF(E29<=参数底稿!$E$6,1,1+9*(E29-参数底稿!$E$6)/(参数底稿!$F$6-参数底稿!$E$6)))) -> 6.6364443 | H29: =0.7*F29+0.3*G29 -> 4.4059856
A30: 营收碳排放 | B30: 重庆钢铁 | C30: 4.2614888 | D30: 3.9778219 | E30: -0.071312119 | F30: =IF(ISBLANK(C30),0,IF(C30<=参数底稿!$E$5,10,IF(C30>=参数底稿!$F$5,1,1+9*(参数底稿!$F$5-C30)/(参数底稿!$F$5-参数底稿!$E$5)))) -> 2.7832383 | G30: =IF(ISBLANK(E30),0,IF(E30>=参数底稿!$F$6,10,IF(E30<=参数底稿!$E$6,1,1+9*(E30-参数底稿!$E$6)/(参数底稿!$F$6-参数底稿!$E$6)))) -> 6.0541182 | H30: =0.7*F30+0.3*G30 -> 3.7645023
A31: 营收碳排放 | B31: 山东钢铁 | C31: 3.2876946 | D31: 3.0041448 | E31: -0.094386197 | F31: =IF(ISBLANK(C31),0,IF(C31<=参数底稿!$E$5,10,IF(C31>=参数底稿!$F$5,1,1+9*(参数底稿!$F$5-C31)/(参数底稿!$F$5-参数底稿!$E$5)))) -> 6.4338454 | G31: =IF(ISBLANK(E31),0,IF(E31>=参数底稿!$F$6,10,IF(E31<=参数底稿!$E$6,1,1+9*(E31-参数底稿!$E$6)/(参数底稿!$F$6-参数底稿!$E$6)))) -> 5.159751 | H31: =0.7*F31+0.3*G31 -> 6.0516171
A32: 营收碳排放 | B32: 马钢股份 | C32: 4.5051762 | D32: 3.9297338 | E32: -0.14643293 | F32: =IF(ISBLANK(C32),0,IF(C32<=参数底稿!$E$5,10,IF(C32>=参数底稿!$F$5,1,1+9*(参数底稿!$F$5-C32)/(参数底稿!$F$5-参数底稿!$E$5)))) -> 1.869691 | G32: =IF(ISBLANK(E32),0,IF(E32>=参数底稿!$F$6,10,IF(E32<=参数底稿!$E$6,1,1+9*(E32-参数底稿!$E$6)/(参数底稿!$F$6-参数底稿!$E$6)))) -> 3.1423838 | H32: =0.7*F32+0.3*G32 -> 2.2514988
A33: 营收碳排放 | B33: 南钢股份 | C33: 3.2842051 | D33: 2.8465875 | E33: -0.15373409 | F33: =IF(ISBLANK(C33),0,IF(C33<=参数底稿!$E$5,10,IF(C33>=参数底稿!$F$5,1,1+9*(参数底稿!$F$5-C33)/(参数底稿!$F$5-参数底稿!$E$5)))) -> 6.4469271 | G33: =IF(ISBLANK(E33),0,IF(E33>=参数底稿!$F$6,10,IF(E33<=参数底稿!$E$6,1,1+9*(E33-参数底稿!$E$6)/(参数底稿!$F$6-参数底稿!$E$6)))) -> 2.8593858 | H33: =0.7*F33+0.3*G33 -> 5.3706647
A34: 营收碳排放 | B34: 中南股份 | C34: 4.5419554 | D34: 3.7422464 | E34: -0.21369758 | F34: =IF(ISBLANK(C34),0,IF(C34<=参数底稿!$E$5,10,IF(C34>=参数底稿!$F$5,1,1+9*(参数底稿!$F$5-C34)/(参数底稿!$F$5-参数底稿!$E$5)))) -> 1.7318115 | G34: =IF(ISBLANK(E34),0,IF(E34>=参数底稿!$F$6,10,IF(E34<=参数底稿!$E$6,1,1+9*(E34-参数底稿!$E$6)/(参数底稿!$F$6-参数底稿!$E$6)))) -> 1 | H34: =0.7*F34+0.3*G34 -> 1.512268
A35: 营收碳排放 | B35: 新钢股份 | C35: 4.9684241 | D35: 3.0248935 | E35: -0.64251205 | F35: =IF(ISBLANK(C35),0,IF(C35<=参数底稿!$E$5,10,IF(C35>=参数底稿!$F$5,1,1+9*(参数底稿!$F$5-C35)/(参数底稿!$F$5-参数底稿!$E$5)))) -> 1 | G35: =IF(ISBLANK(E35),0,IF(E35>=参数底稿!$F$6,10,IF(E35<=参数底稿!$E$6,1,1+9*(E35-参数底稿!$E$6)/(参数底稿!$F$6-参数底稿!$E$6)))) -> 1 | H35: =0.7*F35+0.3*G35 -> 1
A36: 营收碳排放 | B36: 华菱钢铁 | F36: =IF(ISBLANK(C36),0,IF(C36<=参数底稿!$E$5,10,IF(C36>=参数底稿!$F$5,1,1+9*(参数底稿!$F$5-C36)/(参数底稿!$F$5-参数底稿!$E$5)))) -> 0 | G36: =IF(ISBLANK(E36),0,IF(E36>=参数底稿!$F$6,10,IF(E36<=参数底稿!$E$6,1,1+9*(E36-参数底稿!$E$6)/(参数底稿!$F$6-参数底稿!$E$6)))) -> 0 | H36: =0.7*F36+0.3*G36 -> 0
A37: 营收碳排放 | B37: 宝武钢铁 | F37: =IF(ISBLANK(C37),0,IF(C37<=参数底稿!$E$5,10,IF(C37>=参数底稿!$F$5,1,1+9*(参数底稿!$F$5-C37)/(参数底稿!$F$5-参数底稿!$E$5)))) -> 0 | G37: =IF(ISBLANK(E37),0,IF(E37>=参数底稿!$F$6,10,IF(E37<=参数底稿!$E$6,1,1+9*(E37-参数底稿!$E$6)/(参数底稿!$F$6-参数底稿!$E$6)))) -> 0 | H37: =0.7*F37+0.3*G37 -> 0
A38: 营收碳排放 | B38: 包钢股份 | F38: =IF(ISBLANK(C38),0,IF(C38<=参数底稿!$E$5,10,IF(C38>=参数底稿!$F$5,1,1+9*(参数底稿!$F$5-C38)/(参数底稿!$F$5-参数底稿!$E$5)))) -> 0 | G38: =IF(ISBLANK(E38),0,IF(E38>=参数底稿!$F$6,10,IF(E38<=参数底稿!$E$6,1,1+9*(E38-参数底稿!$E$6)/(参数底稿!$F$6-参数底稿!$E$6)))) -> 0 | H38: =0.7*F38+0.3*G38 -> 0
A39: 营收碳排放 | B39: 鞍钢股份 | F39: =IF(ISBLANK(C39),0,IF(C39<=参数底稿!$E$5,10,IF(C39>=参数底稿!$F$5,1,1+9*(参数底稿!$F$5-C39)/(参数底稿!$F$5-参数底稿!$E$5)))) -> 0 | G39: =IF(ISBLANK(E39),0,IF(E39>=参数底稿!$F$6,10,IF(E39<=参数底稿!$E$6,1,1+9*(E39-参数底稿!$E$6)/(参数底稿!$F$6-参数底稿!$E$6)))) -> 0 | H39: =0.7*F39+0.3*G39 -> 0
A40: 营收碳排放 | B40: 本钢板材 | F40: =IF(ISBLANK(C40),0,IF(C40<=参数底稿!$E$5,10,IF(C40>=参数底稿!$F$5,1,1+9*(参数底稿!$F$5-C40)/(参数底稿!$F$5-参数底稿!$E$5)))) -> 0 | G40: =IF(ISBLANK(E40),0,IF(E40>=参数底稿!$F$6,10,IF(E40<=参数底稿!$E$6,1,1+9*(E40-参数底稿!$E$6)/(参数底稿!$F$6-参数底稿!$E$6)))) -> 0 | H40: =0.7*F40+0.3*G40 -> 0
A41: 营收碳排放 | B41: 凌钢股份 | F41: =IF(ISBLANK(C41),0,IF(C41<=参数底稿!$E$5,10,IF(C41>=参数底稿!$F$5,1,1+9*(参数底稿!$F$5-C41)/(参数底稿!$F$5-参数底稿!$E$5)))) -> 0 | G41: =IF(ISBLANK(E41),0,IF(E41>=参数底稿!$F$6,10,IF(E41<=参数底稿!$E$6,1,1+9*(E41-参数底稿!$E$6)/(参数底稿!$F$6-参数底稿!$E$6)))) -> 0 | H41: =0.7*F41+0.3*G41 -> 0
...

Sheet 参数底稿
A1: 指标 | B1: 维度 | C1: 方向 | D1: 数据量 | E1: P10 | F1: P90 | G1: Span(P90-P10)
A2: 物理碳排放 | B2: 行业维度70% | C2: ↓低好 | D2: 14 | E2: 1.539141 | F2: 2.128523 | G2: 0.589382
A3: 物理碳排放 | B3: 自身维度30% | C3: ↑高好 | D3: 13 | E3: -0.062903 | F3: 0.058469 | G3: 0.121372
A5: 营收碳排放 | B5: 行业维度70% | C5: ↓低好 | D5: 14 | E5: 2.336428 | F5: 4.737165 | G5: 2.400736
A6: 营收碳排放 | B6: 自身维度30% | C6: ↑高好 | D6: 13 | E6: -0.201705 | F6: 0.030489 | G6: 0.232193
A8: 用水效率 | B8: 行业维度70% | C8: ↓低好 | D8: 19 | E8: 1.342 | F8: 3.524 | G8: 2.182
A9: 用水效率 | B9: 自身维度30% | C9: ↑高好 | D9: 17 | E9: -0.082025 | F9: 0.154146 | G9: 0.236171
A11: 自发可再生电量 | B11: 行业维度70% | C11: ↑高好 | D11: 16 | E11: 0.000179 | F11: 0.065213 | G11: 0.065034
A12: 自发可再生电量 | B12: 自身维度30% | C12: ↑高好 | D12: 14 | E12: -0.084002 | F12: 0.722751 | G12: 0.806754
A14: 外购绿电 | B14: 行业维度70% | C14: ↑高好 | D14: 12 | E14: 0.00359 | F14: 0.10952 | G14: 0.10593
A15: 外购绿电 | B15: 自身维度30% | C15: ↑高好 | D15: 10 | E15: 0.001539 | F15: 5.31016 | G15: 5.308621
A17: 研发投入占比 | B17: 行业维度70% | C17: ↑高好 | D17: 20 | E17: 0.001664 | F17: 0.039424 | G17: 0.03776
A18: 研发投入占比 | B18: 自身维度30% | C18: ↑高好 | D18: 20 | E18: -0.050337 | F18: 0.316321 | G18: 0.366657
... A30: 稳就业促就业 | B30: 综合100% | C30: ↑高好 | D30: 20 | E30: -0.085962 | F30: 0.066072 | G30: 0.152034
